<?xml version="1.0"?>
<robot xmlns:xacro="http://www.ros.org/wiki/xacro">
    <xacro:macro name="gripper" params="prefix">
        <link name="${prefix}_gripper_base_link">
        <visual>
        <origin xyz="-0.04015 0.0144875 -0.0347028" rpy="-1.31921 -1.52407 -0.251324" />
        <geometry>
        <mesh filename="package://ob1_arm_description/meshes/hk15328d_v5.stl"/>
        </geometry>
        <material name="hk15328d_v5_material">
        <color rgba="0.952941 0.796078 0.486275 1.0"/>
        </material>
        </visual>
        <collision>
        <origin xyz="-0.04015 0.0144875 -0.0347028" rpy="-1.31921 -1.52407 -0.251324" />
        <geometry>
        <mesh filename="package://ob1_arm_description/meshes/hk15328d_v5.stl"/>
        </geometry>
        <material name="hk15328d_v5_material">
        <color rgba="0.952941 0.796078 0.486275 1.0"/>
        </material>
        </collision>
        <visual>
        <origin xyz="-0.04015 0.0239869 -0.0345924" rpy="0.251587 -1.52407 -0.251324" />
        <geometry>
        <mesh filename="package://ob1_arm_description/meshes/spur_gear_(16_teeth).stl"/>
        </geometry>
        <material name="spur_gear_(16_teeth)_material">
        <color rgba="0.615686 0.811765 0.929412 1.0"/>
        </material>
        </visual>
        <collision>
        <origin xyz="-0.04015 0.0239869 -0.0345924" rpy="0.251587 -1.52407 -0.251324" />
        <geometry>
        <mesh filename="package://ob1_arm_description/meshes/spur_gear_(16_teeth).stl"/>
        </geometry>
        <material name="spur_gear_(16_teeth)_material">
        <color rgba="0.615686 0.811765 0.929412 1.0"/>
        </material>
        </collision>
        <visual>
        <origin xyz="-0.04 0.019 -0.0535151" rpy="-3.14159 -0.174533 4.4254e-17" />
        <geometry>
        <mesh filename="package://ob1_arm_description/meshes/spur_gear_(36_teeth).stl"/>
        </geometry>
        <material name="spur_gear_(36_teeth)_material">
        <color rgba="0.647059 0.647059 0.647059 1.0"/>
        </material>
        </visual>
        <collision>
        <origin xyz="-0.04 0.019 -0.0535151" rpy="-3.14159 -0.174533 4.4254e-17" />
        <geometry>
        <mesh filename="package://ob1_arm_description/meshes/spur_gear_(36_teeth).stl"/>
        </geometry>
        <material name="spur_gear_(36_teeth)_material">
        <color rgba="0.647059 0.647059 0.647059 1.0"/>
        </material>
        </collision>
        <visual>
        <origin xyz="6.93889e-18 -8.67362e-19 -1.77636e-15" rpy="-3.14159 1.01857e-14 5.54818e-17" />
        <geometry>
        <mesh filename="package://ob1_arm_description/meshes/part_2_gripper.stl"/>
        </geometry>
        <material name="part_2_gripper_material">
        <color rgba="0.917647 0.917647 0.917647 1.0"/>
        </material>
        </visual>
        <collision>
        <origin xyz="6.93889e-18 -8.67362e-19 -1.77636e-15" rpy="-3.14159 1.01857e-14 5.54818e-17" />
        <geometry>
        <mesh filename="package://ob1_arm_description/meshes/part_2_gripper.stl"/>
        </geometry>
        <material name="part_2_gripper_material">
        <color rgba="0.917647 0.917647 0.917647 1.0"/>
        </material>
        </collision>
        <visual>
        <origin xyz="0.04015 0.0239869 -0.0345924" rpy="3.10536 -1.244 -3.10728" />
        <geometry>
        <mesh filename="package://ob1_arm_description/meshes/spur_gear_(16_teeth).stl"/>
        </geometry>
        <material name="spur_gear_(16_teeth)_material">
        <color rgba="0.615686 0.811765 0.929412 1.0"/>
        </material>
        </visual>
        <collision>
        <origin xyz="0.04015 0.0239869 -0.0345924" rpy="3.10536 -1.244 -3.10728" />
        <geometry>
        <mesh filename="package://ob1_arm_description/meshes/spur_gear_(16_teeth).stl"/>
        </geometry>
        <material name="spur_gear_(16_teeth)_material">
        <color rgba="0.615686 0.811765 0.929412 1.0"/>
        </material>
        </collision>
        <visual>
        <origin xyz="0.04 0.024 -0.0535151" rpy="1.10827e-14 1.0192e-14 1.02561e-16" />
        <geometry>
        <mesh filename="package://ob1_arm_description/meshes/spur_gear_(36_teeth).stl"/>
        </geometry>
        <material name="spur_gear_(36_teeth)_material">
        <color rgba="0.647059 0.647059 0.647059 1.0"/>
        </material>
        </visual>
        <collision>
        <origin xyz="0.04 0.024 -0.0535151" rpy="1.10827e-14 1.0192e-14 1.02561e-16" />
        <geometry>
        <mesh filename="package://ob1_arm_description/meshes/spur_gear_(36_teeth).stl"/>
        </geometry>
        <material name="spur_gear_(36_teeth)_material">
        <color rgba="0.647059 0.647059 0.647059 1.0"/>
        </material>
        </collision>
        <visual>
        <origin xyz="0.04015 0.0144875 -0.0347028" rpy="1.53457 -1.244 -3.10728" />
        <geometry>
        <mesh filename="package://ob1_arm_description/meshes/hk15328d_v5.stl"/>
        </geometry>
        <material name="hk15328d_v5_material">
        <color rgba="0.952941 0.796078 0.486275 1.0"/>
        </material>
        </visual>
        <collision>
        <origin xyz="0.04015 0.0144875 -0.0347028" rpy="1.53457 -1.244 -3.10728" />
        <geometry>
        <mesh filename="package://ob1_arm_description/meshes/hk15328d_v5.stl"/>
        </geometry>
        <material name="hk15328d_v5_material">
        <color rgba="0.952941 0.796078 0.486275 1.0"/>
        </material>
        </collision>
        <visual>
        <origin xyz="0.04015 0.0144875 -0.0347028" rpy="8.11517e-13 1.55917 1.5708" />
        <geometry>
        <mesh filename="package://ob1_arm_description/meshes/hk15328d_v5.stl"/>
        </geometry>
        <material name="hk15328d_v5_material">
        <color rgba="0.392157 0.403922 0.384314 1.0"/>
        </material>
        </visual>
        <collision>
        <origin xyz="0.04015 0.0144875 -0.0347028" rpy="8.11517e-13 1.55917 1.5708" />
        <geometry>
        <mesh filename="package://ob1_arm_description/meshes/hk15328d_v5.stl"/>
        </geometry>
        <material name="hk15328d_v5_material">
        <color rgba="0.392157 0.403922 0.384314 1.0"/>
        </material>
        </collision>
        <visual>
        <origin xyz="-0.04015 0.0144875 -0.0347028" rpy="-1.23792e-12 -1.55917 -1.5708" />
        <geometry>
        <mesh filename="package://ob1_arm_description/meshes/hk15328d_v5.stl"/>
        </geometry>
        <material name="hk15328d_v5_material">
        <color rgba="0.392157 0.403922 0.384314 1.0"/>
        </material>
        </visual>
        <collision>
        <origin xyz="-0.04015 0.0144875 -0.0347028" rpy="-1.23792e-12 -1.55917 -1.5708" />
        <geometry>
        <mesh filename="package://ob1_arm_description/meshes/hk15328d_v5.stl"/>
        </geometry>
        <material name="hk15328d_v5_material">
        <color rgba="0.392157 0.403922 0.384314 1.0"/>
        </material>
        </collision>
        <visual>
        <origin xyz="3.46945e-18 -8.67362e-19 -1.11022e-16" rpy="3.14159 -6.62591e-19 -1.44439e-17" />
        <geometry>
        <mesh filename="package://ob1_arm_description/meshes/part_1_gripper.stl"/>
        </geometry>
        <material name="part_1_gripper_material">
        <color rgba="0.615686 0.811765 0.929412 1.0"/>
        </material>
        </visual>
        <collision>
        <origin xyz="3.46945e-18 -8.67362e-19 -1.11022e-16" rpy="3.14159 -6.62591e-19 -1.44439e-17" />
        <geometry>
        <mesh filename="package://ob1_arm_description/meshes/part_1_gripper.stl"/>
        </geometry>
        <material name="part_1_gripper_material">
        <color rgba="0.615686 0.811765 0.929412 1.0"/>
        </material>
        </collision>
        <inertial>
        <origin xyz="0 0 0" rpy="0 0 0"/>
        <mass value="0" />
        <inertia ixx="0" ixy="0"  ixz="0" iyy="0" iyz="0" izz="0" />
        </inertial>
        </link>

        <link name="${prefix}_rclaw_link">
        <visual>
        <origin xyz="-0.0203388 -0.0331036 0.037" rpy="1.5708 -1.32447e-15 0.332485" />
        <geometry>
        <mesh filename="package://ob1_arm_description/meshes/part_1_mirror_gripper_claw.stl"/>
        </geometry>
        <material name="part_1_mirror_gripper_claw_material">
        <color rgba="0.615686 0.811765 0.929412 1.0"/>
        </material>
        </visual>
        <collision>
        <origin xyz="-0.0203388 -0.0331036 0.037" rpy="1.5708 -1.32447e-15 0.332485" />
        <geometry>
        <mesh filename="package://ob1_arm_description/meshes/part_1_mirror_gripper_claw.stl"/>
        </geometry>
        <material name="part_1_mirror_gripper_claw_material">
        <color rgba="0.615686 0.811765 0.929412 1.0"/>
        </material>
        </collision>
        <visual>
        <origin xyz="0.0106217 -0.0304372 0.012" rpy="1.5708 2.79276e-18 -8.04372e-17" />
        <geometry>
        <mesh filename="package://ob1_arm_description/meshes/part_3_mirror_gripper_claw.stl"/>
        </geometry>
        <material name="part_3_mirror_gripper_claw_material">
        <color rgba="0.231373 0.380392 0.705882 1.0"/>
        </material>
        </visual>
        <collision>
        <origin xyz="0.0106217 -0.0304372 0.012" rpy="1.5708 2.79276e-18 -8.04372e-17" />
        <geometry>
        <mesh filename="package://ob1_arm_description/meshes/part_3_mirror_gripper_claw.stl"/>
        </geometry>
        <material name="part_3_mirror_gripper_claw_material">
        <color rgba="0.231373 0.380392 0.705882 1.0"/>
        </material>
        </collision>
        <visual>
        <origin xyz="0.0114671 -0.0521066 0.013" rpy="-1.5708 -5.46252e-16 -1.22447" />
        <geometry>
        <mesh filename="package://ob1_arm_description/meshes/part_2_mirror_gripper_claw.stl"/>
        </geometry>
        <material name="part_2_mirror_gripper_claw_material">
        <color rgba="0.647059 0.647059 0.647059 1.0"/>
        </material>
        </visual>
        <collision>
        <origin xyz="0.0114671 -0.0521066 0.013" rpy="-1.5708 -5.46252e-16 -1.22447" />
        <geometry>
        <mesh filename="package://ob1_arm_description/meshes/part_2_mirror_gripper_claw.stl"/>
        </geometry>
        <material name="part_2_mirror_gripper_claw_material">
        <color rgba="0.647059 0.647059 0.647059 1.0"/>
        </material>
        </collision>
        <inertial>
        <origin xyz="0 0 0" rpy="0 0 0"/>
        <mass value="0" />
        <inertia ixx="0" ixy="0"  ixz="0" iyy="0" iyz="0" izz="0" />
        </inertial>
        </link>

        <link name="${prefix}_lclaw_link">
        <visual>
        <origin xyz="-0.00826547 -0.051955 0.013" rpy="-1.5708 -3.1668e-17 1.26775" />
        <geometry>
        <mesh filename="package://ob1_arm_description/meshes/part_2_gripper_claw.stl"/>
        </geometry>
        <material name="part_2_gripper_claw_material">
        <color rgba="0.647059 0.647059 0.647059 1.0"/>
        </material>
        </visual>
        <collision>
        <origin xyz="-0.00826547 -0.051955 0.013" rpy="-1.5708 -3.1668e-17 1.26775" />
        <geometry>
        <mesh filename="package://ob1_arm_description/meshes/part_2_gripper_claw.stl"/>
        </geometry>
        <material name="part_2_gripper_claw_material">
        <color rgba="0.647059 0.647059 0.647059 1.0"/>
        </material>
        </collision>
        <visual>
        <origin xyz="-0.0106217 -0.0304372 0.012" rpy="1.5708 -6.24126e-18 1.52187e-17" />
        <geometry>
        <mesh filename="package://ob1_arm_description/meshes/part_3_gripper_claw.stl"/>
        </geometry>
        <material name="part_3_gripper_claw_material">
        <color rgba="0.231373 0.380392 0.705882 1.0"/>
        </material>
        </visual>
        <collision>
        <origin xyz="-0.0106217 -0.0304372 0.012" rpy="1.5708 -6.24126e-18 1.52187e-17" />
        <geometry>
        <mesh filename="package://ob1_arm_description/meshes/part_3_gripper_claw.stl"/>
        </geometry>
        <material name="part_3_gripper_claw_material">
        <color rgba="0.231373 0.380392 0.705882 1.0"/>
        </material>
        </collision>
        <visual>
        <origin xyz="0.022895 -0.0320261 0.037" rpy="1.5708 -8.52418e-17 -0.296946" />
        <geometry>
        <mesh filename="package://ob1_arm_description/meshes/part_1_gripper_claw.stl"/>
        </geometry>
        <material name="part_1_gripper_claw_material">
        <color rgba="0.615686 0.811765 0.929412 1.0"/>
        </material>
        </visual>
        <collision>
        <origin xyz="0.022895 -0.0320261 0.037" rpy="1.5708 -8.52418e-17 -0.296946" />
        <geometry>
        <mesh filename="package://ob1_arm_description/meshes/part_1_gripper_claw.stl"/>
        </geometry>
        <material name="part_1_gripper_claw_material">
        <color rgba="0.615686 0.811765 0.929412 1.0"/>
        </material>
        </collision>
        <inertial>
        <origin xyz="0 0 0" rpy="0 0 0"/>
        <mass value="0" />
        <inertia ixx="0" ixy="0"  ixz="0" iyy="0" iyz="0" izz="0" />eef
        </inertial>
        </link>

        <joint name="${prefix}_gripper_lclaw_joint" type="revolute">
        <origin xyz="-0.04 0.008 -0.0535151" rpy="1.5708 -0.367452 -8.36952e-16" />
        <parent link="${prefix}_gripper_base_link" />
        <child link="${prefix}_lclaw_link" />
        <axis xyz="0 0 1"/>
        <limit effort="1" velocity="20" lower="-3.14" upper="3.14"/>
        <joint_properties friction="0.0"/>
        <dynamics D="1" K="7000" mu_coulomb="0" mu_viscous="16" damping="0.003" friction="0.0"/>
        </joint>

        <joint name="${prefix}_gripper_rclaw_joint" type="revolute">
        <origin xyz="0.04 0.008 -0.0535151" rpy="1.5708 0.450222 1.06462e-15" />
        <parent link="${prefix}_gripper_base_link" />
        <child link="${prefix}_rclaw_link" />
        <axis xyz="0 0 1"/>
        <limit effort="1" velocity="20" lower="-3.14" upper="3.14"/>
        <joint_properties friction="0.0"/>
        <dynamics D="1" K="7000" mu_coulomb="0" mu_viscous="16" damping="0.003" friction="0.0"/>
        </joint>

        <link name="${prefix}_eef_link">
            <inertial>
                <origin xyz="0 0 0" rpy="0 0 0"/>
                <mass value="0" />
                <inertia ixx="0" ixy="0"  ixz="0" iyy="0" iyz="0" izz="0" />
            </inertial>
        </link>
        <joint name="${prefix}_gripper_eef_link" type="fixed">
            <origin xyz="0 0 -0.11" rpy="0 0 0" />
            <parent link="${prefix}_gripper_base_link" />
            <child link="${prefix}_eef_link" />
        </joint>

    </xacro:macro>
</robot>
