<?xml version="1.0"?>
<robot xmlns:xacro="http://www.ros.org/wiki/xacro" name="robot">
    <xacro:macro name="arm" params="prefix">
        <link name="${prefix}_base_link">
        <visual>
        <origin xyz="3.31402e-16 -0.0195 0.06" rpy="-1.5708 1.21431e-16 3.90606e-18" />
        <geometry>
        <mesh filename="package://ob1_arm_description/meshes/shoulder_y_motor.stl"/>
        </geometry>
        <material name="shoulder_y_motor_material">
        <color rgba="0.615686 0.811765 0.929412 1.0"/>
        </material>
        </visual>
        <collision>
        <origin xyz="3.31402e-16 -0.0195 0.06" rpy="-1.5708 1.21431e-16 3.90606e-18" />
        <geometry>
        <mesh filename="package://ob1_arm_description/meshes/shoulder_y_motor.stl"/>
        </geometry>
        <material name="shoulder_y_motor_material">
        <color rgba="0.615686 0.811765 0.929412 1.0"/>
        </material>
        </collision>
        <visual>
        <origin xyz="1.33481e-16 -0.0195 0.06" rpy="-1.5708 1.2013e-16 2.92997e-21" />
        <geometry>
        <mesh filename="package://ob1_arm_description/meshes/shoulder_plate.stl"/>
        </geometry>
        <material name="shoulder_plate_material">
        <color rgba="0.231373 0.380392 0.705882 1.0"/>
        </material>
        </visual>
        <collision>
        <origin xyz="1.33481e-16 -0.0195 0.06" rpy="-1.5708 1.2013e-16 2.92997e-21" />
        <geometry>
        <mesh filename="package://ob1_arm_description/meshes/shoulder_plate.stl"/>
        </geometry>
        <material name="shoulder_plate_material">
        <color rgba="0.231373 0.380392 0.705882 1.0"/>
        </material>
        </collision>
        <visual>
        <origin xyz="3.46418e-16 -0.0195 0.06" rpy="-1.5708 1.20997e-16 7.25353e-18" />
        <geometry>
        <mesh filename="package://ob1_arm_description/meshes/motor_front_support_-_shoulder.stl"/>
        </geometry>
        <material name="motor_front_support_-_shoulder_material">
        <color rgba="0.498039 0.498039 0.498039 1.0"/>
        </material>
        </visual>
        <collision>
        <origin xyz="3.46418e-16 -0.0195 0.06" rpy="-1.5708 1.20997e-16 7.25353e-18" />
        <geometry>
        <mesh filename="package://ob1_arm_description/meshes/motor_front_support_-_shoulder.stl"/>
        </geometry>
        <material name="motor_front_support_-_shoulder_material">
        <color rgba="0.498039 0.498039 0.498039 1.0"/>
        </material>
        </collision>
        <visual>
        <origin xyz="-6.34937e-17 -0.0195 0.06" rpy="-1.5708 1.2013e-16 2.92997e-21" />
        <geometry>
        <mesh filename="package://ob1_arm_description/meshes/motor_mid_support_-_shoulder.stl"/>
        </geometry>
        <material name="motor_mid_support_-_shoulder_material">
        <color rgba="0.972549 0.529412 0.00392157 1.0"/>
        </material>
        </visual>
        <collision>
        <origin xyz="-6.34937e-17 -0.0195 0.06" rpy="-1.5708 1.2013e-16 2.92997e-21" />
        <geometry>
        <mesh filename="package://ob1_arm_description/meshes/motor_mid_support_-_shoulder.stl"/>
        </geometry>
        <material name="motor_mid_support_-_shoulder_material">
        <color rgba="0.972549 0.529412 0.00392157 1.0"/>
        </material>
        </collision>
        <inertial>
        <origin xyz="0 0 0" rpy="0 0 0"/>
        <mass value="0" />link name
        <inertia ixx="0" ixy="0"  ixz="0" iyy="0" iyz="0" izz="0" />
        </inertial>
        </link>

        <link name="${prefix}_shoulder_link">
        <visual>
        <origin xyz="-2.6024e-17 0.15 0.067" rpy="-3.14159 1.29296e-31 1.06311e-31" />
        <geometry>
        <mesh filename="package://ob1_arm_description/meshes/shoulder_linkage_-_motor.stl"/>
        </geometry>
        <material name="shoulder_linkage_-_motor_material">
        <color rgba="0.921569 0.8 0.654902 1.0"/>
        </material>
        </visual>
        <collision>
        <origin xyz="-2.6024e-17 0.15 0.067" rpy="-3.14159 1.29296e-31 1.06311e-31" />
        <geometry>
        <mesh filename="package://ob1_arm_description/meshes/shoulder_linkage_-_motor.stl"/>
        </geometry>
        <material name="shoulder_linkage_-_motor_material">
        <color rgba="0.921569 0.8 0.654902 1.0"/>
        </material>
        </collision>
        <visual>
        <origin xyz="8.73083e-16 5.96745e-16 0.067" rpy="-3.14159 5.82402e-30 3.40006e-16" />
        <geometry>
        <mesh filename="package://ob1_arm_description/meshes/bicep_y_motor.stl"/>
        </geometry>
        <material name="bicep_y_motor_material">
        <color rgba="0.615686 0.811765 0.929412 1.0"/>
        </material>
        </visual>
        <collision>
        <origin xyz="8.73083e-16 5.96745e-16 0.067" rpy="-3.14159 5.82402e-30 3.40006e-16" />
        <geometry>
        <mesh filename="package://ob1_arm_description/meshes/bicep_y_motor.stl"/>
        </geometry>
        <material name="bicep_y_motor_material">
        <color rgba="0.615686 0.811765 0.929412 1.0"/>
        </material>
        </collision>
        <visual>
        <origin xyz="1.05176e-15 1.01308e-15 0.067" rpy="-3.14159 1.33273e-30 5.55112e-17" />
        <geometry>
        <mesh filename="package://ob1_arm_description/meshes/motor_front_support_-_bicep.stl"/>
        </geometry>
        <material name="motor_front_support_-_bicep_material">
        <color rgba="0.498039 0.498039 0.498039 1.0"/>
        </material>
        </visual>
        <collision>
        <origin xyz="1.05176e-15 1.01308e-15 0.067" rpy="-3.14159 1.33273e-30 5.55112e-17" />
        <geometry>
        <mesh filename="package://ob1_arm_description/meshes/motor_front_support_-_bicep.stl"/>
        </geometry>
        <material name="motor_front_support_-_bicep_material">
        <color rgba="0.498039 0.498039 0.498039 1.0"/>
        </material>
        </collision>
        <visual>
        <origin xyz="1.05696e-15 1.0339e-15 0.067" rpy="-3.14159 8.66334e-31 -6.93889e-18" />
        <geometry>
        <mesh filename="package://ob1_arm_description/meshes/bicep_plate_-_real.stl"/>
        </geometry>
        <material name="bicep_plate_-_real_material">
        <color rgba="0.980392 0.713725 0.00392157 1.0"/>
        </material>
        </visual>
        <collision>
        <origin xyz="1.05696e-15 1.0339e-15 0.067" rpy="-3.14159 8.66334e-31 -6.93889e-18" />
        <geometry>
        <mesh filename="package://ob1_arm_description/meshes/bicep_plate_-_real.stl"/>
        </geometry>
        <material name="bicep_plate_-_real_material">
        <color rgba="0.980392 0.713725 0.00392157 1.0"/>
        </material>
        </collision>
        <visual>
        <origin xyz="9.47676e-16 9.02056e-16 0.067" rpy="-3.14159 2.04671e-30 2.56739e-16" />
        <geometry>
        <mesh filename="package://ob1_arm_description/meshes/shoulder_linkage_-_encoder.stl"/>
        </geometry>
        <material name="shoulder_linkage_-_encoder_material">
        <color rgba="0.615686 0.811765 0.929412 1.0"/>
        </material>
        </visual>
        <collision>
        <origin xyz="9.47676e-16 9.02056e-16 0.067" rpy="-3.14159 2.04671e-30 2.56739e-16" />
        <geometry>
        <mesh filename="package://ob1_arm_description/meshes/shoulder_linkage_-_encoder.stl"/>
        </geometry>
        <material name="shoulder_linkage_-_encoder_material">
        <color rgba="0.615686 0.811765 0.929412 1.0"/>
        </material>
        </collision>
        <visual>
        <origin xyz="1.11291e-15 1.02002e-15 0.067" rpy="-3.14159 -7.11387e-31 -6.93889e-18" />
        <geometry>
        <mesh filename="package://ob1_arm_description/meshes/motor_mid_support_-_bicep.stl"/>
        </geometry>
        <material name="motor_mid_support_-_bicep_material">
        <color rgba="0.972549 0.529412 0.00392157 1.0"/>
        </material>
        </visual>
        <collision>
        <origin xyz="1.11291e-15 1.02002e-15 0.067" rpy="-3.14159 -7.11387e-31 -6.93889e-18" />
        <geometry>
        <mesh filename="package://ob1_arm_description/meshes/motor_mid_support_-_bicep.stl"/>
        </geometry>
        <material name="motor_mid_support_-_bicep_material">
        <color rgba="0.972549 0.529412 0.00392157 1.0"/>
        </material>
        </collision>
        <inertial>
        <origin xyz="0 0 0" rpy="0 0 0"/>
        <mass value="0" />
        <inertia ixx="0" ixy="0"  ixz="0" iyy="0" iyz="0" izz="0" />
        </inertial>
        </link>

        <link name="${prefix}_arm_link">
        <visual>
        <origin xyz="0.00366704 -1.16573e-15 0.0666521" rpy="-3.14159 0.18918 1.10363e-15" />
        <geometry>
        <mesh filename="package://ob1_arm_description/meshes/forearm_z_motor_shaft_collar_-_9604t12_flange-mount_shaft_collar.stl"/>
        </geometry>
        <material name="forearm_z_motor_shaft_collar_-_9604t12_flange-mount_shaft_collar_material">
        <color rgba="0.498039 0.498039 0.498039 1.0"/>
        </material>
        </visual>
        <collision>
        <origin xyz="0.00366704 -1.16573e-15 0.0666521" rpy="-3.14159 0.18918 1.10363e-15" />
        <geometry>
        <mesh filename="package://ob1_arm_description/meshes/forearm_z_motor_shaft_collar_-_9604t12_flange-mount_shaft_collar.stl"/>
        </geometry>
        <material name="forearm_z_motor_shaft_collar_-_9604t12_flange-mount_shaft_collar_material">
        <color rgba="0.498039 0.498039 0.498039 1.0"/>
        </material>
        </collision>
        <visual>
        <origin xyz="-2.10075e-15 -2.77556e-17 0.067" rpy="-3.14159 -8.45674e-31 7.48062e-29" />
        <geometry>
        <mesh filename="package://ob1_arm_description/meshes/bicep_z_motor.stl"/>
        </geometry>
        <material name="bicep_z_motor_material">
        <color rgba="0.231373 0.380392 0.705882 1.0"/>
        </material>
        </visual>
        <collision>
        <origin xyz="-2.10075e-15 -2.77556e-17 0.067" rpy="-3.14159 -8.45674e-31 7.48062e-29" />
        <geometry>
        <mesh filename="package://ob1_arm_description/meshes/bicep_z_motor.stl"/>
        </geometry>
        <material name="bicep_z_motor_material">
        <color rgba="0.231373 0.380392 0.705882 1.0"/>
        </material>
        </collision>
        <visual>
        <origin xyz="-2.10942e-15 8.60423e-16 0.067" rpy="-3.14159 -8.45674e-31 7.52006e-29" />
        <geometry>
        <mesh filename="package://ob1_arm_description/meshes/bicep_linkage_-_encoder.stl"/>
        </geometry>
        <material name="bicep_linkage_-_encoder_material">
        <color rgba="0.768627 0.886275 0.952941 1.0"/>
        </material>
        </visual>
        <collision>
        <origin xyz="-2.10942e-15 8.60423e-16 0.067" rpy="-3.14159 -8.45674e-31 7.52006e-29" />
        <geometry>
        <mesh filename="package://ob1_arm_description/meshes/bicep_linkage_-_encoder.stl"/>
        </geometry>
        <material name="bicep_linkage_-_encoder_material">
        <color rgba="0.768627 0.886275 0.952941 1.0"/>
        </material>
        </collision>
        <visual>
        <origin xyz="1.97215e-31 0 0.067" rpy="3.14159 7.32047e-31 -1.35585e-31" />
        <geometry>
        <mesh filename="package://ob1_arm_description/meshes/bicep_linkage_-_motor.stl"/>
        </geometry>
        <material name="bicep_linkage_-_motor_material">
        <color rgba="0.647059 0.647059 0.647059 1.0"/>
        </material>
        </visual>
        <collision>
        <origin xyz="1.97215e-31 0 0.067" rpy="3.14159 7.32047e-31 -1.35585e-31" />
        <geometry>
        <mesh filename="package://ob1_arm_description/meshes/bicep_linkage_-_motor.stl"/>
        </geometry>
        <material name="bicep_linkage_-_motor_material">
        <color rgba="0.647059 0.647059 0.647059 1.0"/>
        </material>
        </collision>
        <visual>
        <origin xyz="-2.04524e-15 2.08167e-15 0.067" rpy="-3.14159 7.32047e-31 7.48062e-29" />
        <geometry>
        <mesh filename="package://ob1_arm_description/meshes/forearm_plate.stl"/>
        </geometry>
        <material name="forearm_plate_material">
        <color rgba="0.647059 0.647059 0.647059 1.0"/>
        </material>
        </visual>
        <collision>
        <origin xyz="-2.04524e-15 2.08167e-15 0.067" rpy="-3.14159 7.32047e-31 7.48062e-29" />
        <geometry>
        <mesh filename="package://ob1_arm_description/meshes/forearm_plate.stl"/>
        </geometry>
        <material name="forearm_plate_material">
        <color rgba="0.647059 0.647059 0.647059 1.0"/>
        </material>
        </collision>
        <inertial>
        <origin xyz="0 0 0" rpy="0 0 0"/>
        <mass value="0" />
        <inertia ixx="0" ixy="0"  ixz="0" iyy="0" iyz="0" izz="0" />
        </inertial>
        </link>

        <link name="${prefix}_elbow_link">
        <visual>
        <origin xyz="-6.10257e-17 0.0195 0.18" rpy="1.5708 -3.50057e-30 6.24005e-16" />
        <geometry>
        <mesh filename="package://ob1_arm_description/meshes/forearm_motor_support.stl"/>
        </geometry>
        <material name="forearm_motor_support_material">
        <color rgba="0.917647 0.917647 0.917647 1.0"/>
        </material>
        </visual>
        <collision>
        <origin xyz="-6.10257e-17 0.0195 0.18" rpy="1.5708 -3.50057e-30 6.24005e-16" />
        <geometry>
        <mesh filename="package://ob1_arm_description/meshes/forearm_motor_support.stl"/>
        </geometry>
        <material name="forearm_motor_support_material">
        <color rgba="0.917647 0.917647 0.917647 1.0"/>
        </material>
        </collision>
        <visual>
        <origin xyz="-1.24534e-17 0.0195 0.18" rpy="1.5708 -1.47911e-31 1.94071e-32" />
        <geometry>
        <mesh filename="package://ob1_arm_description/meshes/forearm_intermediate_plate.stl"/>
        </geometry>
        <material name="forearm_intermediate_plate_material">
        <color rgba="0.980392 0.713725 0.00392157 1.0"/>
        </material>
        </visual>
        <collision>
        <origin xyz="-1.24534e-17 0.0195 0.18" rpy="1.5708 -1.47911e-31 1.94071e-32" />
        <geometry>
        <mesh filename="package://ob1_arm_description/meshes/forearm_intermediate_plate.stl"/>
        </geometry>
        <material name="forearm_intermediate_plate_material">
        <color rgba="0.980392 0.713725 0.00392157 1.0"/>
        </material>
        </collision>
        <visual>
        <origin xyz="7.60004e-16 0.05285 -0.03115" rpy="1.5708 8.32667e-16 1.94491e-15" />
        <geometry>
        <mesh filename="package://ob1_arm_description/meshes/part_1.stl"/>
        </geometry>
        <material name="part_1_material">
        <color rgba="0.615686 0.811765 0.929412 1.0"/>
        </material>
        </visual>
        <collision>
        <origin xyz="7.60004e-16 0.05285 -0.03115" rpy="1.5708 8.32667e-16 1.94491e-15" />
        <geometry>
        <mesh filename="package://ob1_arm_description/meshes/part_1.stl"/>
        </geometry>
        <material name="part_1_material">
        <color rgba="0.615686 0.811765 0.929412 1.0"/>
        </material>
        </collision>
        <inertial>
        <origin xyz="0 0 0" rpy="0 0 0"/>
        <mass value="0" />
        <inertia ixx="0" ixy="0"  ixz="0" iyy="0" iyz="0" izz="0" />
        </inertial>
        </link>

        <link name="${prefix}_forearm_link">
        <visual>
        <origin xyz="-1.4988e-15 0.21115 0.06335" rpy="6.48455e-30 -1.50196e-29 2.14577e-17" />
        <geometry>
        <mesh filename="package://ob1_arm_description/meshes/end_effector_plate.stl"/>
        </geometry>
        <material name="end_effector_plate_material">
        <color rgba="0.972549 0.529412 0.00392157 1.0"/>
        </material>
        </visual>
        <collision>
        <origin xyz="-1.4988e-15 0.21115 0.06335" rpy="6.48455e-30 -1.50196e-29 2.14577e-17" />
        <geometry>
        <mesh filename="package://ob1_arm_description/meshes/end_effector_plate.stl"/>
        </geometry>
        <material name="end_effector_plate_material">
        <color rgba="0.972549 0.529412 0.00392157 1.0"/>
        </material>
        </collision>
        <visual>
        <origin xyz="1.56819e-15 0.21115 0.06335" rpy="4.6717e-30 -7.41629e-30 2.61753e-17" />
        <geometry>
        <mesh filename="package://ob1_arm_description/meshes/forearm_linkage_-_encoder.stl"/>
        </geometry>
        <material name="forearm_linkage_-_encoder_material">
        <color rgba="0.768627 0.886275 0.952941 1.0"/>
        </material>
        </visual>
        <collision>
        <origin xyz="1.56819e-15 0.21115 0.06335" rpy="4.6717e-30 -7.41629e-30 2.61753e-17" />
        <geometry>
        <mesh filename="package://ob1_arm_description/meshes/forearm_linkage_-_encoder.stl"/>
        </geometry>
        <material name="forearm_linkage_-_encoder_material">
        <color rgba="0.768627 0.886275 0.952941 1.0"/>
        </material>
        </collision>
        <visual>
        <origin xyz="0 0.21115 0.06335" rpy="4.53788e-30 7.57625e-31 2.14577e-17" />
        <geometry>
        <mesh filename="package://ob1_arm_description/meshes/forearm_linkage_-_motor.stl"/>
        </geometry>
        <material name="forearm_linkage_-_motor_material">
        <color rgba="0.654902 0.823529 0.576471 1.0"/>
        </material>
        </visual>
        <collision>
        <origin xyz="0 0.21115 0.06335" rpy="4.53788e-30 7.57625e-31 2.14577e-17" />
        <geometry>
        <mesh filename="package://ob1_arm_description/meshes/forearm_linkage_-_motor.stl"/>
        </geometry>
        <material name="forearm_linkage_-_motor_material">
        <color rgba="0.654902 0.823529 0.576471 1.0"/>
        </material>
        </collision>
        <visual>
        <origin xyz="4.38538e-15 0.21115 0.06335" rpy="5.07568e-30 -3.09221e-32 1.54084e-18" />
        <geometry>
        <mesh filename="package://ob1_arm_description/meshes/wrist_z_motor.stl"/>
        </geometry>
        <material name="wrist_z_motor_material">
        <color rgba="0.498039 0.498039 0.498039 1.0"/>
        </material>
        </visual>
        <collision>
        <origin xyz="4.38538e-15 0.21115 0.06335" rpy="5.07568e-30 -3.09221e-32 1.54084e-18" />
        <geometry>
        <mesh filename="package://ob1_arm_description/meshes/wrist_z_motor.stl"/>
        </geometry>
        <material name="wrist_z_motor_material">
        <color rgba="0.498039 0.498039 0.498039 1.0"/>
        </material>
        </collision>
        <inertial>
        <origin xyz="0 0 0" rpy="0 0 0"/>
        <mass value="0" />
        <inertia ixx="0" ixy="0"  ixz="0" iyy="0" iyz="0" izz="0" />
        </inertial>
        </link>

        <joint name="${prefix}_elbow_forearm_joint" type="revolute">
        <origin xyz="7.84649e-16 0.08285 -0.03115" rpy="1.5708 0.220816 1.70392e-15" />
        <parent link="${prefix}_elbow_link" />
        <child link="${prefix}_forearm_link" />
        <axis xyz="0 0 1"/>
        <limit effort="1" velocity="20" lower="-3.14" upper="3.14"/>
        <joint_properties friction="0.0"/>
        <dynamics D="1" K="7000" mu_coulomb="0" mu_viscous="16" damping="0.003" friction="0.0"/>
        </joint>

        <joint name="${prefix}_arm_elbow_joint" type="revolute">
        <origin xyz="-1.32468e-15 0.18 0.0475" rpy="1.5708 9.77638e-15 -5.07927e-15" />
        <parent link="${prefix}_arm_link" />
        <child link="${prefix}_elbow_link" />
        <axis xyz="0 0 1"/>
        <limit effort="1" velocity="20" lower="-3.14" upper="3.14"/>
        <joint_properties friction="0.0"/>
        <dynamics D="1" K="7000" mu_coulomb="0" mu_viscous="16" damping="0.003" friction="0.0"/>
        </joint>

        <joint name="${prefix}_shoulder_arm" type="revolute">
        <origin xyz="2.98296e-16 0.15 -8.32667e-16" rpy="2.02357e-15 -1.3664e-14 -5.20417e-16" />
        <parent link="${prefix}_shoulder_link" />
        <child link="${prefix}_arm_link" />
        <axis xyz="0 0 1"/>
        <limit effort="1" velocity="20" lower="-3.14" upper="3.14"/>
        <joint_properties friction="0.0"/>
        <dynamics D="1" K="7000" mu_coulomb="0" mu_viscous="16" damping="0.003" friction="0.0"/>
        </joint>

        <joint name="${prefix}_base_shoulder" type="revolute">
        <origin xyz="8.04497e-17 0.0475 0.06" rpy="1.5708 -3.9066e-15 5.32612e-15" />
        <parent link="${prefix}_base_link" />
        <child link="${prefix}_shoulder_link" />
        <axis xyz="0 0 1"/>
        <limit effort="1" velocity="20" lower="-3.14" upper="3.14"/>
        <joint_properties friction="0.0"/>
        <dynamics D="1" K="7000" mu_coulomb="0" mu_viscous="16" damping="0.003" friction="0.0"/>
        </joint>


    </xacro:macro>
</robot>