<?xml version="1.0"?>
<robot xmlns:xacro="http://www.ros.org/wiki/xacro" name="robot">
    <xacro:macro name="arm" params="prefix">
        <link name="${prefix}_base_link">
        <visual>
        <origin xyz="3.31402e-16 -0.0195 0.06" rpy="-1.5708 1.21431e-16 3.90606e-18" />
        <geometry>
        <mesh filename="package://ob1_arm_description/meshes/shoulder_y_motor.stl"/>
        </geometry>
        <material name="shoulder_y_motor_material">
        <color rgba="0.615686 0.811765 0.929412 1.0"/>
        </material>
        </visual>
        <collision>
        <origin xyz="3.31402e-16 -0.0195 0.06" rpy="-1.5708 1.21431e-16 3.90606e-18" />
        <geometry>
        <mesh filename="package://ob1_arm_description/meshes/shoulder_y_motor.stl"/>
        </geometry>
        <material name="shoulder_y_motor_material">
        <color rgba="0.615686 0.811765 0.929412 1.0"/>
        </material>
        </collision>
        <visual>
        <origin xyz="1.33481e-16 -0.0195 0.06" rpy="-1.5708 1.2013e-16 2.92997e-21" />
        <geometry>
        <mesh filename="package://ob1_arm_description/meshes/shoulder_plate.stl"/>
        </geometry>
        <material name="shoulder_plate_material">
        <color rgba="0.231373 0.380392 0.705882 1.0"/>
        </material>
        </visual>
        <collision>
        <origin xyz="1.33481e-16 -0.0195 0.06" rpy="-1.5708 1.2013e-16 2.92997e-21" />
        <geometry>
        <mesh filename="package://ob1_arm_description/meshes/shoulder_plate.stl"/>
        </geometry>
        <material name="shoulder_plate_material">
        <color rgba="0.231373 0.380392 0.705882 1.0"/>
        </material>
        </collision>
        <visual>
        <origin xyz="3.46418e-16 -0.0195 0.06" rpy="-1.5708 1.20997e-16 7.25353e-18" />
        <geometry>
        <mesh filename="package://ob1_arm_description/meshes/motor_front_support_-_shoulder.stl"/>
        </geometry>
        <material name="motor_front_support_-_shoulder_material">
        <color rgba="0.498039 0.498039 0.498039 1.0"/>
        </material>
        </visual>
        <collision>
        <origin xyz="3.46418e-16 -0.0195 0.06" rpy="-1.5708 1.20997e-16 7.25353e-18" />
        <geometry>
        <mesh filename="package://ob1_arm_description/meshes/motor_front_support_-_shoulder.stl"/>
        </geometry>
        <material name="motor_front_support_-_shoulder_material">
        <color rgba="0.498039 0.498039 0.498039 1.0"/>
        </material>
        </collision>
        <visual>
        <origin xyz="-6.34937e-17 -0.0195 0.06" rpy="-1.5708 1.2013e-16 2.92997e-21" />
        <geometry>
        <mesh filename="package://ob1_arm_description/meshes/motor_mid_support_-_shoulder.stl"/>
        </geometry>
        <material name="motor_mid_support_-_shoulder_material">
        <color rgba="0.972549 0.529412 0.00392157 1.0"/>
        </material>
        </visual>
        <collision>
        <origin xyz="-6.34937e-17 -0.0195 0.06" rpy="-1.5708 1.2013e-16 2.92997e-21" />
        <geometry>
        <mesh filename="package://ob1_arm_description/meshes/motor_mid_support_-_shoulder.stl"/>
        </geometry>
        <material name="motor_mid_support_-_shoulder_material">
        <color rgba="0.972549 0.529412 0.00392157 1.0"/>
        </material>
        </collision>
        <inertial>
        <origin xyz="0 0 0" rpy="0 0 0"/>
        <mass value="0" />
        <inertia ixx="0" ixy="0"  ixz="0" iyy="0" iyz="0" izz="0" />
        </inertial>
        </link>

        <link name="${prefix}_shoulder_link">
        <visual>
        <origin xyz="-2.59124e-17 0.15 0.067" rpy="3.14159 -2.02376e-31 3.10097e-18" />
        <geometry>
        <mesh filename="package://ob1_arm_description/meshes/shoulder_linkage_-_motor.stl"/>
        </geometry>
        <material name="shoulder_linkage_-_motor_material">
        <color rgba="0.921569 0.8 0.654902 1.0"/>
        </material>
        </visual>
        <collision>
        <origin xyz="-2.59124e-17 0.15 0.067" rpy="3.14159 -2.02376e-31 3.10097e-18" />
        <geometry>
        <mesh filename="package://ob1_arm_description/meshes/shoulder_linkage_-_motor.stl"/>
        </geometry>
        <material name="shoulder_linkage_-_motor_material">
        <color rgba="0.921569 0.8 0.654902 1.0"/>
        </material>
        </collision>
        <visual>
        <origin xyz="8.79071e-16 6.245e-16 0.067" rpy="-3.14159 6.26309e-30 3.30936e-16" />
        <geometry>
        <mesh filename="package://ob1_arm_description/meshes/bicep_y_motor.stl"/>
        </geometry>
        <material name="bicep_y_motor_material">
        <color rgba="0.615686 0.811765 0.929412 1.0"/>
        </material>
        </visual>
        <collision>
        <origin xyz="8.79071e-16 6.245e-16 0.067" rpy="-3.14159 6.26309e-30 3.30936e-16" />
        <geometry>
        <mesh filename="package://ob1_arm_description/meshes/bicep_y_motor.stl"/>
        </geometry>
        <material name="bicep_y_motor_material">
        <color rgba="0.615686 0.811765 0.929412 1.0"/>
        </material>
        </collision>
        <visual>
        <origin xyz="1.03715e-15 1.04083e-15 0.067" rpy="-3.14159 1.39936e-30 -2.98503e-17" />
        <geometry>
        <mesh filename="package://ob1_arm_description/meshes/motor_front_support_-_bicep.stl"/>
        </geometry>
        <material name="motor_front_support_-_bicep_material">
        <color rgba="0.498039 0.498039 0.498039 1.0"/>
        </material>
        </visual>
        <collision>
        <origin xyz="1.03715e-15 1.04083e-15 0.067" rpy="-3.14159 1.39936e-30 -2.98503e-17" />
        <geometry>
        <mesh filename="package://ob1_arm_description/meshes/motor_front_support_-_bicep.stl"/>
        </geometry>
        <material name="motor_front_support_-_bicep_material">
        <color rgba="0.498039 0.498039 0.498039 1.0"/>
        </material>
        </collision>
        <visual>
        <origin xyz="1.05677e-15 1.06859e-15 0.067" rpy="-3.14159 1.84829e-30 -7.32146e-17" />
        <geometry>
        <mesh filename="package://ob1_arm_description/meshes/bicep_plate_-_real.stl"/>
        </geometry>
        <material name="bicep_plate_-_real_material">
        <color rgba="0.980392 0.713725 0.00392157 1.0"/>
        </material>
        </visual>
        <collision>
        <origin xyz="1.05677e-15 1.06859e-15 0.067" rpy="-3.14159 1.84829e-30 -7.32146e-17" />
        <geometry>
        <mesh filename="package://ob1_arm_description/meshes/bicep_plate_-_real.stl"/>
        </geometry>
        <material name="bicep_plate_-_real_material">
        <color rgba="0.980392 0.713725 0.00392157 1.0"/>
        </material>
        </collision>
        <visual>
        <origin xyz="9.52797e-16 9.57567e-16 0.067" rpy="-3.14159 1.97023e-30 1.36668e-16" />
        <geometry>
        <mesh filename="package://ob1_arm_description/meshes/shoulder_linkage_-_encoder.stl"/>
        </geometry>
        <material name="shoulder_linkage_-_encoder_material">
        <color rgba="0.615686 0.811765 0.929412 1.0"/>
        </material>
        </visual>
        <collision>
        <origin xyz="9.52797e-16 9.57567e-16 0.067" rpy="-3.14159 1.97023e-30 1.36668e-16" />
        <geometry>
        <mesh filename="package://ob1_arm_description/meshes/shoulder_linkage_-_encoder.stl"/>
        </geometry>
        <material name="shoulder_linkage_-_encoder_material">
        <color rgba="0.615686 0.811765 0.929412 1.0"/>
        </material>
        </collision>
        <visual>
        <origin xyz="1.11651e-15 1.05471e-15 0.067" rpy="-3.14159 2.70566e-31 -7.32146e-17" />
        <geometry>
        <mesh filename="package://ob1_arm_description/meshes/motor_mid_support_-_bicep.stl"/>
        </geometry>
        <material name="motor_mid_support_-_bicep_material">
        <color rgba="0.972549 0.529412 0.00392157 1.0"/>
        </material>
        </visual>
        <collision>
        <origin xyz="1.11651e-15 1.05471e-15 0.067" rpy="-3.14159 2.70566e-31 -7.32146e-17" />
        <geometry>
        <mesh filename="package://ob1_arm_description/meshes/motor_mid_support_-_bicep.stl"/>
        </geometry>
        <material name="motor_mid_support_-_bicep_material">
        <color rgba="0.972549 0.529412 0.00392157 1.0"/>
        </material>
        </collision>
        <inertial>
        <origin xyz="0 0 0" rpy="0 0 0"/>
        <mass value="0" />
        <inertia ixx="0" ixy="0"  ixz="0" iyy="0" iyz="0" izz="0" />
        </inertial>
        </link>

        <link name="${prefix}_arm_link">
        <visual>
        <origin xyz="0.00366704 -1.27676e-15 0.0666521" rpy="-3.14159 0.18918 1.80411e-15" />
        <geometry>
        <mesh filename="package://ob1_arm_description/meshes/forearm_z_motor_shaft_collar_-_9604t12_flange-mount_shaft_collar.stl"/>
        </geometry>
        <material name="forearm_z_motor_shaft_collar_-_9604t12_flange-mount_shaft_collar_material">
        <color rgba="0.498039 0.498039 0.498039 1.0"/>
        </material>
        </visual>
        <collision>
        <origin xyz="0.00366704 -1.27676e-15 0.0666521" rpy="-3.14159 0.18918 1.80411e-15" />
        <geometry>
        <mesh filename="package://ob1_arm_description/meshes/forearm_z_motor_shaft_collar_-_9604t12_flange-mount_shaft_collar.stl"/>
        </geometry>
        <material name="forearm_z_motor_shaft_collar_-_9604t12_flange-mount_shaft_collar_material">
        <color rgba="0.498039 0.498039 0.498039 1.0"/>
        </material>
        </collision>
        <visual>
        <origin xyz="-2.13371e-15 -1.38778e-16 0.067" rpy="-3.14159 2.13756e-29 -1.6944e-16" />
        <geometry>
        <mesh filename="package://ob1_arm_description/meshes/bicep_z_motor.stl"/>
        </geometry>
        <material name="bicep_z_motor_material">
        <color rgba="0.231373 0.380392 0.705882 1.0"/>
        </material>
        </visual>
        <collision>
        <origin xyz="-2.13371e-15 -1.38778e-16 0.067" rpy="-3.14159 2.13756e-29 -1.6944e-16" />
        <geometry>
        <mesh filename="package://ob1_arm_description/meshes/bicep_z_motor.stl"/>
        </geometry>
        <material name="bicep_z_motor_material">
        <color rgba="0.231373 0.380392 0.705882 1.0"/>
        </material>
        </collision>
        <visual>
        <origin xyz="-2.12851e-15 8.04912e-16 0.067" rpy="-3.14159 2.13756e-29 -1.6944e-16" />
        <geometry>
        <mesh filename="package://ob1_arm_description/meshes/bicep_linkage_-_encoder.stl"/>
        </geometry>
        <material name="bicep_linkage_-_encoder_material">
        <color rgba="0.768627 0.886275 0.952941 1.0"/>
        </material>
        </visual>
        <collision>
        <origin xyz="-2.12851e-15 8.04912e-16 0.067" rpy="-3.14159 2.13756e-29 -1.6944e-16" />
        <geometry>
        <mesh filename="package://ob1_arm_description/meshes/bicep_linkage_-_encoder.stl"/>
        </geometry>
        <material name="bicep_linkage_-_encoder_material">
        <color rgba="0.768627 0.886275 0.952941 1.0"/>
        </material>
        </collision>
        <visual>
        <origin xyz="1.73472e-18 -2.77556e-17 0.067" rpy="-3.14159 -8.22245e-32 -2.84672e-18" />
        <geometry>
        <mesh filename="package://ob1_arm_description/meshes/bicep_linkage_-_motor.stl"/>
        </geometry>
        <material name="bicep_linkage_-_motor_material">
        <color rgba="0.647059 0.647059 0.647059 1.0"/>
        </material>
        </visual>
        <collision>
        <origin xyz="1.73472e-18 -2.77556e-17 0.067" rpy="-3.14159 -8.22245e-32 -2.84672e-18" />
        <geometry>
        <mesh filename="package://ob1_arm_description/meshes/bicep_linkage_-_motor.stl"/>
        </geometry>
        <material name="bicep_linkage_-_motor_material">
        <color rgba="0.647059 0.647059 0.647059 1.0"/>
        </material>
        </collision>
        <visual>
        <origin xyz="-2.0834e-15 2.02616e-15 0.067" rpy="-3.14159 3.58504e-30 -7.91075e-17" />
        <geometry>
        <mesh filename="package://ob1_arm_description/meshes/forearm_plate.stl"/>
        </geometry>
        <material name="forearm_plate_material">
        <color rgba="0.647059 0.647059 0.647059 1.0"/>
        </material>
        </visual>
        <collision>
        <origin xyz="-2.0834e-15 2.02616e-15 0.067" rpy="-3.14159 3.58504e-30 -7.91075e-17" />
        <geometry>
        <mesh filename="package://ob1_arm_description/meshes/forearm_plate.stl"/>
        </geometry>
        <material name="forearm_plate_material">
        <color rgba="0.647059 0.647059 0.647059 1.0"/>
        </material>
        </collision>
        <inertial>
        <origin xyz="0 0 0" rpy="0 0 0"/>
        <mass value="0" />
        <inertia ixx="0" ixy="0"  ixz="0" iyy="0" iyz="0" izz="0" />
        </inertial>
        </link>

        <link name="${prefix}_elbow_link">
        <visual>
        <origin xyz="-1.14492e-16 0.0195 0.18" rpy="1.5708 2.04915e-16 7.13982e-16" />
        <geometry>
        <mesh filename="package://ob1_arm_description/meshes/forearm_motor_support.stl"/>
        </geometry>
        <material name="forearm_motor_support_material">
        <color rgba="0.917647 0.917647 0.917647 1.0"/>
        </material>
        </visual>
        <collision>
        <origin xyz="-1.14492e-16 0.0195 0.18" rpy="1.5708 2.04915e-16 7.13982e-16" />
        <geometry>
        <mesh filename="package://ob1_arm_description/meshes/forearm_motor_support.stl"/>
        </geometry>
        <material name="forearm_motor_support_material">
        <color rgba="0.917647 0.917647 0.917647 1.0"/>
        </material>
        </collision>
        <visual>
        <origin xyz="-1.56125e-17 0.0195 0.18" rpy="1.5708 4.02585e-18 2.26158e-19" />
        <geometry>
        <mesh filename="package://ob1_arm_description/meshes/forearm_intermediate_plate.stl"/>
        </geometry>
        <material name="forearm_intermediate_plate_material">
        <color rgba="0.980392 0.713725 0.00392157 1.0"/>
        </material>
        </visual>
        <collision>
        <origin xyz="-1.56125e-17 0.0195 0.18" rpy="1.5708 4.02585e-18 2.26158e-19" />
        <geometry>
        <mesh filename="package://ob1_arm_description/meshes/forearm_intermediate_plate.stl"/>
        </geometry>
        <material name="forearm_intermediate_plate_material">
        <color rgba="0.980392 0.713725 0.00392157 1.0"/>
        </material>
        </collision>
        <visual>
        <origin xyz="7.32053e-16 0.05285 -0.03115" rpy="1.5708 1.05794e-15 1.82583e-15" />
        <geometry>
        <mesh filename="package://ob1_arm_description/meshes/part_1.stl"/>
        </geometry>
        <material name="part_1_material">
        <color rgba="0.615686 0.811765 0.929412 1.0"/>
        </material>
        </visual>
        <collision>
        <origin xyz="7.32053e-16 0.05285 -0.03115" rpy="1.5708 1.05794e-15 1.82583e-15" />
        <geometry>
        <mesh filename="package://ob1_arm_description/meshes/part_1.stl"/>
        </geometry>
        <material name="part_1_material">
        <color rgba="0.615686 0.811765 0.929412 1.0"/>
        </material>
        </collision>
        <inertial>
        <origin xyz="0 0 0" rpy="0 0 0"/>
        <mass value="0" />
        <inertia ixx="0" ixy="0"  ixz="0" iyy="0" iyz="0" izz="0" />
        </inertial>
        </link>

        <link name="${prefix}_forearm_link">
        <visual>
        <origin xyz="-1.43635e-15 0.21115 0.06335" rpy="1.44226e-20 3.73615e-17 2.30593e-17" />
        <geometry>
        <mesh filename="package://ob1_arm_description/meshes/end_effector_plate.stl"/>
        </geometry>
        <material name="end_effector_plate_material">
        <color rgba="0.972549 0.529412 0.00392157 1.0"/>
        </material>
        </visual>
        <collision>
        <origin xyz="-1.43635e-15 0.21115 0.06335" rpy="1.44226e-20 3.73615e-17 2.30593e-17" />
        <geometry>
        <mesh filename="package://ob1_arm_description/meshes/end_effector_plate.stl"/>
        </geometry>
        <material name="end_effector_plate_material">
        <color rgba="0.972549 0.529412 0.00392157 1.0"/>
        </material>
        </collision>
        <visual>
        <origin xyz="1.5786e-15 0.21115 0.06335" rpy="-1.61808e-19 9.63599e-17 2.17225e-16" />
        <geometry>
        <mesh filename="package://ob1_arm_description/meshes/forearm_linkage_-_encoder.stl"/>
        </geometry>
        <material name="forearm_linkage_-_encoder_material">
        <color rgba="0.768627 0.886275 0.952941 1.0"/>
        </material>
        </visual>
        <collision>
        <origin xyz="1.5786e-15 0.21115 0.06335" rpy="-1.61808e-19 9.63599e-17 2.17225e-16" />
        <geometry>
        <mesh filename="package://ob1_arm_description/meshes/forearm_linkage_-_encoder.stl"/>
        </geometry>
        <material name="forearm_linkage_-_encoder_material">
        <color rgba="0.768627 0.886275 0.952941 1.0"/>
        </material>
        </collision>
        <visual>
        <origin xyz="-1.04083e-17 0.21115 0.06335" rpy="2.64017e-20 6.23759e-20 2.25943e-18" />
        <geometry>
        <mesh filename="package://ob1_arm_description/meshes/forearm_linkage_-_motor.stl"/>
        </geometry>
        <material name="forearm_linkage_-_motor_material">
        <color rgba="0.654902 0.823529 0.576471 1.0"/>
        </material>
        </visual>
        <collision>
        <origin xyz="-1.04083e-17 0.21115 0.06335" rpy="2.64017e-20 6.23759e-20 2.25943e-18" />
        <geometry>
        <mesh filename="package://ob1_arm_description/meshes/forearm_linkage_-_motor.stl"/>
        </geometry>
        <material name="forearm_linkage_-_motor_material">
        <color rgba="0.654902 0.823529 0.576471 1.0"/>
        </material>
        </collision>
        <visual>
        <origin xyz="4.17721e-15 0.21115 0.06335" rpy="-2.34386e-19 3.24406e-16 6.50284e-17" />
        <geometry>
        <mesh filename="package://ob1_arm_description/meshes/wrist_z_motor.stl"/>
        </geometry>
        <material name="wrist_z_motor_material">
        <color rgba="0.498039 0.498039 0.498039 1.0"/>
        </material>
        </visual>
        <collision>
        <origin xyz="4.17721e-15 0.21115 0.06335" rpy="-2.34386e-19 3.24406e-16 6.50284e-17" />
        <geometry>
        <mesh filename="package://ob1_arm_description/meshes/wrist_z_motor.stl"/>
        </geometry>
        <material name="wrist_z_motor_material">
        <color rgba="0.498039 0.498039 0.498039 1.0"/>
        </material>
        </collision>
        <inertial>
        <origin xyz="0 0 0" rpy="0 0 0"/>
        <mass value="0" />
        <inertia ixx="0" ixy="0"  ixz="0" iyy="0" iyz="0" izz="0" />
        </inertial>
        </link>

        <joint name="${prefix}_elbow_forearm_joint" type="revolute">
        <origin xyz="7.71952e-16 0.08285 -0.03115" rpy="1.5708 0.0729385 1.34977e-15" />
        <parent link="${prefix}_elbow_link" />
        <child link="${prefix}_forearm_link" />
        <axis xyz="0 0 1"/>
        <limit effort="1" velocity="20" lower="-1.5787" upper="1.5787"/>
        <joint_properties friction="0.0"/>
        <dynamics D="1" K="7000" mu_coulomb="0" mu_viscous="16" damping="0.003" friction="0.0"/>
        </joint>

        <joint name="${prefix}_arm_elbow_joint" type="revolute">
        <origin xyz="-1.33227e-15 0.18 0.0475" rpy="1.5708 0.00373826 -5.38613e-15" />
        <parent link="${prefix}_arm_link" />
        <child link="${prefix}_elbow_link" />
        <axis xyz="0 0 1"/>
        <limit effort="1" velocity="20" lower="-3.14" upper="3.14"/>
        <joint_properties friction="0.0"/>
        <dynamics D="1" K="7000" mu_coulomb="0" mu_viscous="16" damping="0.003" friction="0.0"/>
        </joint>

        <joint name="${prefix}_shoulder_arm_joint" type="revolute">
        <origin xyz="2.90241e-16 0.15 -7.97973e-16" rpy="8.20328e-16 -1.37552e-14 -0.046259" />
        <parent link="${prefix}_shoulder_link" />
        <child link="${prefix}_arm_link" />
        <axis xyz="0 0 1"/>
        <limit effort="1" velocity="20" lower="-1.5787" upper="1.5787"/>
        <joint_properties friction="0.0"/>
        <dynamics D="1" K="7000" mu_coulomb="0" mu_viscous="16" damping="0.003" friction="0.0"/>
        </joint>

        <joint name="${prefix}_base_shoulder_joint" type="revolute">
        <origin xyz="8.1532e-17 0.0475 0.06" rpy="1.5708 -0.0134839 4.87562e-15" />
        <parent link="${prefix}_base_link" />
        <child link="${prefix}_shoulder_link" />
        <axis xyz="0 0 1"/>
        <limit effort="1" velocity="20" lower="-1.5787" upper="1.5787"/>
        <joint_properties friction="0.0"/>
        <dynamics D="1" K="7000" mu_coulomb="0" mu_viscous="16" damping="0.003" friction="0.0"/>
        </joint>
    </xacro:macro>
</robot>