<robot name="onshape">
<link name="base_link">
<visual>
<origin xyz="3.31402e-16 -0.0195 0.06" rpy="-1.5708 1.21431e-16 3.90606e-18" />
<geometry>
<mesh filename="package://shoulder_y_motor.stl"/>
</geometry>
<material name="shoulder_y_motor_material">
<color rgba="0.615686 0.811765 0.929412 1.0"/>
</material>
</visual>
<collision>
<origin xyz="3.31402e-16 -0.0195 0.06" rpy="-1.5708 1.21431e-16 3.90606e-18" />
<geometry>
<mesh filename="package://shoulder_y_motor.stl"/>
</geometry>
<material name="shoulder_y_motor_material">
<color rgba="0.615686 0.811765 0.929412 1.0"/>
</material>
</collision>
<visual>
<origin xyz="1.33481e-16 -0.0195 0.06" rpy="-1.5708 1.2013e-16 2.92997e-21" />
<geometry>
<mesh filename="package://shoulder_plate.stl"/>
</geometry>
<material name="shoulder_plate_material">
<color rgba="0.231373 0.380392 0.705882 1.0"/>
</material>
</visual>
<collision>
<origin xyz="1.33481e-16 -0.0195 0.06" rpy="-1.5708 1.2013e-16 2.92997e-21" />
<geometry>
<mesh filename="package://shoulder_plate.stl"/>
</geometry>
<material name="shoulder_plate_material">
<color rgba="0.231373 0.380392 0.705882 1.0"/>
</material>
</collision>
<visual>
<origin xyz="3.46418e-16 -0.0195 0.06" rpy="-1.5708 1.20997e-16 7.25353e-18" />
<geometry>
<mesh filename="package://motor_front_support_-_shoulder.stl"/>
</geometry>
<material name="motor_front_support_-_shoulder_material">
<color rgba="0.498039 0.498039 0.498039 1.0"/>
</material>
</visual>
<collision>
<origin xyz="3.46418e-16 -0.0195 0.06" rpy="-1.5708 1.20997e-16 7.25353e-18" />
<geometry>
<mesh filename="package://motor_front_support_-_shoulder.stl"/>
</geometry>
<material name="motor_front_support_-_shoulder_material">
<color rgba="0.498039 0.498039 0.498039 1.0"/>
</material>
</collision>
<visual>
<origin xyz="-6.34937e-17 -0.0195 0.06" rpy="-1.5708 1.2013e-16 2.92997e-21" />
<geometry>
<mesh filename="package://motor_mid_support_-_shoulder.stl"/>
</geometry>
<material name="motor_mid_support_-_shoulder_material">
<color rgba="0.972549 0.529412 0.00392157 1.0"/>
</material>
</visual>
<collision>
<origin xyz="-6.34937e-17 -0.0195 0.06" rpy="-1.5708 1.2013e-16 2.92997e-21" />
<geometry>
<mesh filename="package://motor_mid_support_-_shoulder.stl"/>
</geometry>
<material name="motor_mid_support_-_shoulder_material">
<color rgba="0.972549 0.529412 0.00392157 1.0"/>
</material>
</collision>
<inertial>
<origin xyz="0 0 0" rpy="0 0 0"/>
<mass value="0" />
<inertia ixx="0" ixy="0"  ixz="0" iyy="0" iyz="0" izz="0" />
</inertial>
</link>

<link name="shoulder_link">
<visual>
<origin xyz="-2.6024e-17 0.15 0.067" rpy="-3.14159 1.29296e-31 1.06311e-31" />
<geometry>
<mesh filename="package://shoulder_linkage_-_motor.stl"/>
</geometry>
<material name="shoulder_linkage_-_motor_material">
<color rgba="0.921569 0.8 0.654902 1.0"/>
</material>
</visual>
<collision>
<origin xyz="-2.6024e-17 0.15 0.067" rpy="-3.14159 1.29296e-31 1.06311e-31" />
<geometry>
<mesh filename="package://shoulder_linkage_-_motor.stl"/>
</geometry>
<material name="shoulder_linkage_-_motor_material">
<color rgba="0.921569 0.8 0.654902 1.0"/>
</material>
</collision>
<visual>
<origin xyz="8.73083e-16 5.96745e-16 0.067" rpy="-3.14159 5.82402e-30 3.40006e-16" />
<geometry>
<mesh filename="package://bicep_y_motor.stl"/>
</geometry>
<material name="bicep_y_motor_material">
<color rgba="0.615686 0.811765 0.929412 1.0"/>
</material>
</visual>
<collision>
<origin xyz="8.73083e-16 5.96745e-16 0.067" rpy="-3.14159 5.82402e-30 3.40006e-16" />
<geometry>
<mesh filename="package://bicep_y_motor.stl"/>
</geometry>
<material name="bicep_y_motor_material">
<color rgba="0.615686 0.811765 0.929412 1.0"/>
</material>
</collision>
<visual>
<origin xyz="1.05176e-15 1.01308e-15 0.067" rpy="-3.14159 1.33273e-30 5.55112e-17" />
<geometry>
<mesh filename="package://motor_front_support_-_bicep.stl"/>
</geometry>
<material name="motor_front_support_-_bicep_material">
<color rgba="0.498039 0.498039 0.498039 1.0"/>
</material>
</visual>
<collision>
<origin xyz="1.05176e-15 1.01308e-15 0.067" rpy="-3.14159 1.33273e-30 5.55112e-17" />
<geometry>
<mesh filename="package://motor_front_support_-_bicep.stl"/>
</geometry>
<material name="motor_front_support_-_bicep_material">
<color rgba="0.498039 0.498039 0.498039 1.0"/>
</material>
</collision>
<visual>
<origin xyz="1.05696e-15 1.0339e-15 0.067" rpy="-3.14159 8.66334e-31 -6.93889e-18" />
<geometry>
<mesh filename="package://bicep_plate_-_real.stl"/>
</geometry>
<material name="bicep_plate_-_real_material">
<color rgba="0.980392 0.713725 0.00392157 1.0"/>
</material>
</visual>
<collision>
<origin xyz="1.05696e-15 1.0339e-15 0.067" rpy="-3.14159 8.66334e-31 -6.93889e-18" />
<geometry>
<mesh filename="package://bicep_plate_-_real.stl"/>
</geometry>
<material name="bicep_plate_-_real_material">
<color rgba="0.980392 0.713725 0.00392157 1.0"/>
</material>
</collision>
<visual>
<origin xyz="9.47676e-16 9.02056e-16 0.067" rpy="-3.14159 2.04671e-30 2.56739e-16" />
<geometry>
<mesh filename="package://shoulder_linkage_-_encoder.stl"/>
</geometry>
<material name="shoulder_linkage_-_encoder_material">
<color rgba="0.615686 0.811765 0.929412 1.0"/>
</material>
</visual>
<collision>
<origin xyz="9.47676e-16 9.02056e-16 0.067" rpy="-3.14159 2.04671e-30 2.56739e-16" />
<geometry>
<mesh filename="package://shoulder_linkage_-_encoder.stl"/>
</geometry>
<material name="shoulder_linkage_-_encoder_material">
<color rgba="0.615686 0.811765 0.929412 1.0"/>
</material>
</collision>
<visual>
<origin xyz="1.11291e-15 1.02002e-15 0.067" rpy="-3.14159 -7.11387e-31 -6.93889e-18" />
<geometry>
<mesh filename="package://motor_mid_support_-_bicep.stl"/>
</geometry>
<material name="motor_mid_support_-_bicep_material">
<color rgba="0.972549 0.529412 0.00392157 1.0"/>
</material>
</visual>
<collision>
<origin xyz="1.11291e-15 1.02002e-15 0.067" rpy="-3.14159 -7.11387e-31 -6.93889e-18" />
<geometry>
<mesh filename="package://motor_mid_support_-_bicep.stl"/>
</geometry>
<material name="motor_mid_support_-_bicep_material">
<color rgba="0.972549 0.529412 0.00392157 1.0"/>
</material>
</collision>
<inertial>
<origin xyz="0 0 0" rpy="0 0 0"/>
<mass value="0" />
<inertia ixx="0" ixy="0"  ixz="0" iyy="0" iyz="0" izz="0" />
</inertial>
</link>

<link name="arm_link">
<visual>
<origin xyz="0.00366704 -1.16573e-15 0.0666521" rpy="-3.14159 0.18918 1.10363e-15" />
<geometry>
<mesh filename="package://forearm_z_motor_shaft_collar_-_9604t12_flange-mount_shaft_collar.stl"/>
</geometry>
<material name="forearm_z_motor_shaft_collar_-_9604t12_flange-mount_shaft_collar_material">
<color rgba="0.498039 0.498039 0.498039 1.0"/>
</material>
</visual>
<collision>
<origin xyz="0.00366704 -1.16573e-15 0.0666521" rpy="-3.14159 0.18918 1.10363e-15" />
<geometry>
<mesh filename="package://forearm_z_motor_shaft_collar_-_9604t12_flange-mount_shaft_collar.stl"/>
</geometry>
<material name="forearm_z_motor_shaft_collar_-_9604t12_flange-mount_shaft_collar_material">
<color rgba="0.498039 0.498039 0.498039 1.0"/>
</material>
</collision>
<visual>
<origin xyz="-2.10075e-15 -2.77556e-17 0.067" rpy="-3.14159 -8.45674e-31 7.48062e-29" />
<geometry>
<mesh filename="package://bicep_z_motor.stl"/>
</geometry>
<material name="bicep_z_motor_material">
<color rgba="0.231373 0.380392 0.705882 1.0"/>
</material>
</visual>
<collision>
<origin xyz="-2.10075e-15 -2.77556e-17 0.067" rpy="-3.14159 -8.45674e-31 7.48062e-29" />
<geometry>
<mesh filename="package://bicep_z_motor.stl"/>
</geometry>
<material name="bicep_z_motor_material">
<color rgba="0.231373 0.380392 0.705882 1.0"/>
</material>
</collision>
<visual>
<origin xyz="-2.10942e-15 8.60423e-16 0.067" rpy="-3.14159 -8.45674e-31 7.52006e-29" />
<geometry>
<mesh filename="package://bicep_linkage_-_encoder.stl"/>
</geometry>
<material name="bicep_linkage_-_encoder_material">
<color rgba="0.768627 0.886275 0.952941 1.0"/>
</material>
</visual>
<collision>
<origin xyz="-2.10942e-15 8.60423e-16 0.067" rpy="-3.14159 -8.45674e-31 7.52006e-29" />
<geometry>
<mesh filename="package://bicep_linkage_-_encoder.stl"/>
</geometry>
<material name="bicep_linkage_-_encoder_material">
<color rgba="0.768627 0.886275 0.952941 1.0"/>
</material>
</collision>
<visual>
<origin xyz="1.97215e-31 0 0.067" rpy="3.14159 7.32047e-31 -1.35585e-31" />
<geometry>
<mesh filename="package://bicep_linkage_-_motor.stl"/>
</geometry>
<material name="bicep_linkage_-_motor_material">
<color rgba="0.647059 0.647059 0.647059 1.0"/>
</material>
</visual>
<collision>
<origin xyz="1.97215e-31 0 0.067" rpy="3.14159 7.32047e-31 -1.35585e-31" />
<geometry>
<mesh filename="package://bicep_linkage_-_motor.stl"/>
</geometry>
<material name="bicep_linkage_-_motor_material">
<color rgba="0.647059 0.647059 0.647059 1.0"/>
</material>
</collision>
<visual>
<origin xyz="-2.04524e-15 2.08167e-15 0.067" rpy="-3.14159 7.32047e-31 7.48062e-29" />
<geometry>
<mesh filename="package://forearm_plate.stl"/>
</geometry>
<material name="forearm_plate_material">
<color rgba="0.647059 0.647059 0.647059 1.0"/>
</material>
</visual>
<collision>
<origin xyz="-2.04524e-15 2.08167e-15 0.067" rpy="-3.14159 7.32047e-31 7.48062e-29" />
<geometry>
<mesh filename="package://forearm_plate.stl"/>
</geometry>
<material name="forearm_plate_material">
<color rgba="0.647059 0.647059 0.647059 1.0"/>
</material>
</collision>
<inertial>
<origin xyz="0 0 0" rpy="0 0 0"/>
<mass value="0" />
<inertia ixx="0" ixy="0"  ixz="0" iyy="0" iyz="0" izz="0" />
</inertial>
</link>

<link name="elbow_link">
<visual>
<origin xyz="-6.10257e-17 0.0195 0.18" rpy="1.5708 -3.50057e-30 6.24005e-16" />
<geometry>
<mesh filename="package://forearm_motor_support.stl"/>
</geometry>
<material name="forearm_motor_support_material">
<color rgba="0.917647 0.917647 0.917647 1.0"/>
</material>
</visual>
<collision>
<origin xyz="-6.10257e-17 0.0195 0.18" rpy="1.5708 -3.50057e-30 6.24005e-16" />
<geometry>
<mesh filename="package://forearm_motor_support.stl"/>
</geometry>
<material name="forearm_motor_support_material">
<color rgba="0.917647 0.917647 0.917647 1.0"/>
</material>
</collision>
<visual>
<origin xyz="-1.24534e-17 0.0195 0.18" rpy="1.5708 -1.47911e-31 1.94071e-32" />
<geometry>
<mesh filename="package://forearm_intermediate_plate.stl"/>
</geometry>
<material name="forearm_intermediate_plate_material">
<color rgba="0.980392 0.713725 0.00392157 1.0"/>
</material>
</visual>
<collision>
<origin xyz="-1.24534e-17 0.0195 0.18" rpy="1.5708 -1.47911e-31 1.94071e-32" />
<geometry>
<mesh filename="package://forearm_intermediate_plate.stl"/>
</geometry>
<material name="forearm_intermediate_plate_material">
<color rgba="0.980392 0.713725 0.00392157 1.0"/>
</material>
</collision>
<visual>
<origin xyz="7.60004e-16 0.05285 -0.03115" rpy="1.5708 8.32667e-16 1.94491e-15" />
<geometry>
<mesh filename="package://part_1.stl"/>
</geometry>
<material name="part_1_material">
<color rgba="0.615686 0.811765 0.929412 1.0"/>
</material>
</visual>
<collision>
<origin xyz="7.60004e-16 0.05285 -0.03115" rpy="1.5708 8.32667e-16 1.94491e-15" />
<geometry>
<mesh filename="package://part_1.stl"/>
</geometry>
<material name="part_1_material">
<color rgba="0.615686 0.811765 0.929412 1.0"/>
</material>
</collision>
<inertial>
<origin xyz="0 0 0" rpy="0 0 0"/>
<mass value="0" />
<inertia ixx="0" ixy="0"  ixz="0" iyy="0" iyz="0" izz="0" />
</inertial>
</link>

<link name="forearm_link">
<visual>
<origin xyz="-1.4988e-15 0.21115 0.06335" rpy="6.48455e-30 -1.50196e-29 2.14577e-17" />
<geometry>
<mesh filename="package://end_effector_plate.stl"/>
</geometry>
<material name="end_effector_plate_material">
<color rgba="0.972549 0.529412 0.00392157 1.0"/>
</material>
</visual>
<collision>
<origin xyz="-1.4988e-15 0.21115 0.06335" rpy="6.48455e-30 -1.50196e-29 2.14577e-17" />
<geometry>
<mesh filename="package://end_effector_plate.stl"/>
</geometry>
<material name="end_effector_plate_material">
<color rgba="0.972549 0.529412 0.00392157 1.0"/>
</material>
</collision>
<visual>
<origin xyz="1.56819e-15 0.21115 0.06335" rpy="4.6717e-30 -7.41629e-30 2.61753e-17" />
<geometry>
<mesh filename="package://forearm_linkage_-_encoder.stl"/>
</geometry>
<material name="forearm_linkage_-_encoder_material">
<color rgba="0.768627 0.886275 0.952941 1.0"/>
</material>
</visual>
<collision>
<origin xyz="1.56819e-15 0.21115 0.06335" rpy="4.6717e-30 -7.41629e-30 2.61753e-17" />
<geometry>
<mesh filename="package://forearm_linkage_-_encoder.stl"/>
</geometry>
<material name="forearm_linkage_-_encoder_material">
<color rgba="0.768627 0.886275 0.952941 1.0"/>
</material>
</collision>
<visual>
<origin xyz="0 0.21115 0.06335" rpy="4.53788e-30 7.57625e-31 2.14577e-17" />
<geometry>
<mesh filename="package://forearm_linkage_-_motor.stl"/>
</geometry>
<material name="forearm_linkage_-_motor_material">
<color rgba="0.654902 0.823529 0.576471 1.0"/>
</material>
</visual>
<collision>
<origin xyz="0 0.21115 0.06335" rpy="4.53788e-30 7.57625e-31 2.14577e-17" />
<geometry>
<mesh filename="package://forearm_linkage_-_motor.stl"/>
</geometry>
<material name="forearm_linkage_-_motor_material">
<color rgba="0.654902 0.823529 0.576471 1.0"/>
</material>
</collision>
<visual>
<origin xyz="4.38538e-15 0.21115 0.06335" rpy="5.07568e-30 -3.09221e-32 1.54084e-18" />
<geometry>
<mesh filename="package://wrist_z_motor.stl"/>
</geometry>
<material name="wrist_z_motor_material">
<color rgba="0.498039 0.498039 0.498039 1.0"/>
</material>
</visual>
<collision>
<origin xyz="4.38538e-15 0.21115 0.06335" rpy="5.07568e-30 -3.09221e-32 1.54084e-18" />
<geometry>
<mesh filename="package://wrist_z_motor.stl"/>
</geometry>
<material name="wrist_z_motor_material">
<color rgba="0.498039 0.498039 0.498039 1.0"/>
</material>
</collision>
<inertial>
<origin xyz="0 0 0" rpy="0 0 0"/>
<mass value="0" />
<inertia ixx="0" ixy="0"  ixz="0" iyy="0" iyz="0" izz="0" />
</inertial>
</link>

<link name="gripper_assembly_link">
<visual>
<origin xyz="-0.04015 0.0144875 -0.0347028" rpy="-1.22013e-12 -1.55917 -1.5708" />
<geometry>
<mesh filename="package://hk15328d_v5.stl"/>
</geometry>
<material name="hk15328d_v5_material">
<color rgba="0.392157 0.403922 0.384314 1.0"/>
</material>
</visual>
<collision>
<origin xyz="-0.04015 0.0144875 -0.0347028" rpy="-1.22013e-12 -1.55917 -1.5708" />
<geometry>
<mesh filename="package://hk15328d_v5.stl"/>
</geometry>
<material name="hk15328d_v5_material">
<color rgba="0.392157 0.403922 0.384314 1.0"/>
</material>
</collision>
<visual>
<origin xyz="-0.0382059 -0.005 -0.100345" rpy="-1.34629e-14 -1.35876 1.29259e-14" />
<geometry>
<mesh filename="package://part_2_gripper_claw.stl"/>
</geometry>
<material name="part_2_gripper_claw_material">
<color rgba="0.647059 0.647059 0.647059 1.0"/>
</material>
</visual>
<collision>
<origin xyz="-0.0382059 -0.005 -0.100345" rpy="-1.34629e-14 -1.35876 1.29259e-14" />
<geometry>
<mesh filename="package://part_2_gripper_claw.stl"/>
</geometry>
<material name="part_2_gripper_claw_material">
<color rgba="0.647059 0.647059 0.647059 1.0"/>
</material>
</collision>
<visual>
<origin xyz="-0.0506217 -0.004 -0.0839523" rpy="3.14159 -2.35608e-17 -1.19404e-17" />
<geometry>
<mesh filename="package://part_3_gripper_claw.stl"/>
</geometry>
<material name="part_3_gripper_claw_material">
<color rgba="0.231373 0.380392 0.705882 1.0"/>
</material>
</visual>
<collision>
<origin xyz="-0.0506217 -0.004 -0.0839523" rpy="3.14159 -2.35608e-17 -1.19404e-17" />
<geometry>
<mesh filename="package://part_3_gripper_claw.stl"/>
</geometry>
<material name="part_3_gripper_claw_material">
<color rgba="0.231373 0.380392 0.705882 1.0"/>
</material>
</collision>
<visual>
<origin xyz="-0.0182314 -0.029 -0.0656435" rpy="3.14159 -0.039707 1.67593e-14" />
<geometry>
<mesh filename="package://part_1_gripper_claw.stl"/>
</geometry>
<material name="part_1_gripper_claw_material">
<color rgba="0.615686 0.811765 0.929412 1.0"/>
</material>
</visual>
<collision>
<origin xyz="-0.0182314 -0.029 -0.0656435" rpy="3.14159 -0.039707 1.67593e-14" />
<geometry>
<mesh filename="package://part_1_gripper_claw.stl"/>
</geometry>
<material name="part_1_gripper_claw_material">
<color rgba="0.615686 0.811765 0.929412 1.0"/>
</material>
</collision>
<visual>
<origin xyz="0.0209978 -0.029 -0.0626659" rpy="3.14159 0.073635 1.24744e-14" />
<geometry>
<mesh filename="package://part_1_mirror_gripper_claw.stl"/>
</geometry>
<material name="part_1_mirror_gripper_claw_material">
<color rgba="0.615686 0.811765 0.929412 1.0"/>
</material>
</visual>
<collision>
<origin xyz="0.0209978 -0.029 -0.0626659" rpy="3.14159 0.073635 1.24744e-14" />
<geometry>
<mesh filename="package://part_1_mirror_gripper_claw.stl"/>
</geometry>
<material name="part_1_mirror_gripper_claw_material">
<color rgba="0.615686 0.811765 0.929412 1.0"/>
</material>
</collision>
<visual>
<origin xyz="0.04015 0.0144875 -0.0347028" rpy="-5.18357e-13 1.55917 1.5708" />
<geometry>
<mesh filename="package://hk15328d_v5.stl"/>
</geometry>
<material name="hk15328d_v5_material">
<color rgba="0.392157 0.403922 0.384314 1.0"/>
</material>
</visual>
<collision>
<origin xyz="0.04015 0.0144875 -0.0347028" rpy="-5.18357e-13 1.55917 1.5708" />
<geometry>
<mesh filename="package://hk15328d_v5.stl"/>
</geometry>
<material name="hk15328d_v5_material">
<color rgba="0.392157 0.403922 0.384314 1.0"/>
</material>
</collision>
<visual>
<origin xyz="0.04 0.024 -0.0535151" rpy="-2.85212e-15 -2.06882e-17 -3.79317e-17" />
<geometry>
<mesh filename="package://spur_gear_(36_teeth).stl"/>
</geometry>
<material name="spur_gear_(36_teeth)_material">
<color rgba="0.647059 0.647059 0.647059 1.0"/>
</material>
</visual>
<collision>
<origin xyz="0.04 0.024 -0.0535151" rpy="-2.85212e-15 -2.06882e-17 -3.79317e-17" />
<geometry>
<mesh filename="package://spur_gear_(36_teeth).stl"/>
</geometry>
<material name="spur_gear_(36_teeth)_material">
<color rgba="0.647059 0.647059 0.647059 1.0"/>
</material>
</collision>
<visual>
<origin xyz="2.77556e-16 1.73472e-18 8.88178e-16" rpy="3.14159 -4.38952e-18 -9.64226e-17" />
<geometry>
<mesh filename="package://part_2_gripper.stl"/>
</geometry>
<material name="part_2_gripper_material">
<color rgba="0.917647 0.917647 0.917647 1.0"/>
</material>
</visual>
<collision>
<origin xyz="2.77556e-16 1.73472e-18 8.88178e-16" rpy="3.14159 -4.38952e-18 -9.64226e-17" />
<geometry>
<mesh filename="package://part_2_gripper.stl"/>
</geometry>
<material name="part_2_gripper_material">
<color rgba="0.917647 0.917647 0.917647 1.0"/>
</material>
</collision>
<visual>
<origin xyz="0 1.73472e-18 0" rpy="3.14159 -9.58512e-18 1.23104e-17" />
<geometry>
<mesh filename="package://part_1_gripper.stl"/>
</geometry>
<material name="part_1_gripper_material">
<color rgba="0.615686 0.811765 0.929412 1.0"/>
</material>
</visual>
<collision>
<origin xyz="0 1.73472e-18 0" rpy="3.14159 -9.58512e-18 1.23104e-17" />
<geometry>
<mesh filename="package://part_1_gripper.stl"/>
</geometry>
<material name="part_1_gripper_material">
<color rgba="0.615686 0.811765 0.929412 1.0"/>
</material>
</collision>
<visual>
<origin xyz="-0.04015 0.0144875 -0.0347028" rpy="-1.54483 -1.1065 -0.02322" />
<geometry>
<mesh filename="package://hk15328d_v5.stl"/>
</geometry>
<material name="hk15328d_v5_material">
<color rgba="0.952941 0.796078 0.486275 1.0"/>
</material>
</visual>
<collision>
<origin xyz="-0.04015 0.0144875 -0.0347028" rpy="-1.54483 -1.1065 -0.02322" />
<geometry>
<mesh filename="package://hk15328d_v5.stl"/>
</geometry>
<material name="hk15328d_v5_material">
<color rgba="0.952941 0.796078 0.486275 1.0"/>
</material>
</collision>
<visual>
<origin xyz="-0.04 0.019 -0.0535151" rpy="3.14159 -0.174533 7.48986e-17" />
<geometry>
<mesh filename="package://spur_gear_(36_teeth).stl"/>
</geometry>
<material name="spur_gear_(36_teeth)_material">
<color rgba="0.647059 0.647059 0.647059 1.0"/>
</material>
</visual>
<collision>
<origin xyz="-0.04 0.019 -0.0535151" rpy="3.14159 -0.174533 7.48986e-17" />
<geometry>
<mesh filename="package://spur_gear_(36_teeth).stl"/>
</geometry>
<material name="spur_gear_(36_teeth)_material">
<color rgba="0.647059 0.647059 0.647059 1.0"/>
</material>
</collision>
<visual>
<origin xyz="0.04015 0.0144875 -0.0347028" rpy="-1.44532 -1.47775 -0.124935" />
<geometry>
<mesh filename="package://hk15328d_v5.stl"/>
</geometry>
<material name="hk15328d_v5_material">
<color rgba="0.952941 0.796078 0.486275 1.0"/>
</material>
</visual>
<collision>
<origin xyz="0.04015 0.0144875 -0.0347028" rpy="-1.44532 -1.47775 -0.124935" />
<geometry>
<mesh filename="package://hk15328d_v5.stl"/>
</geometry>
<material name="hk15328d_v5_material">
<color rgba="0.952941 0.796078 0.486275 1.0"/>
</material>
</collision>
<visual>
<origin xyz="0.0391983 -0.005 -0.0996329" rpy="-1.18193e-14 1.32595 4.07848e-14" />
<geometry>
<mesh filename="package://part_2_mirror_gripper_claw.stl"/>
</geometry>
<material name="part_2_mirror_gripper_claw_material">
<color rgba="0.647059 0.647059 0.647059 1.0"/>
</material>
</visual>
<collision>
<origin xyz="0.0391983 -0.005 -0.0996329" rpy="-1.18193e-14 1.32595 4.07848e-14" />
<geometry>
<mesh filename="package://part_2_mirror_gripper_claw.stl"/>
</geometry>
<material name="part_2_mirror_gripper_claw_material">
<color rgba="0.647059 0.647059 0.647059 1.0"/>
</material>
</collision>
<visual>
<origin xyz="0.0506217 -0.004 -0.0839523" rpy="3.14159 -2.35608e-17 -1.19404e-17" />
<geometry>
<mesh filename="package://part_3_mirror_gripper_claw.stl"/>
</geometry>
<material name="part_3_mirror_gripper_claw_material">
<color rgba="0.231373 0.380392 0.705882 1.0"/>
</material>
</visual>
<collision>
<origin xyz="0.0506217 -0.004 -0.0839523" rpy="3.14159 -2.35608e-17 -1.19404e-17" />
<geometry>
<mesh filename="package://part_3_mirror_gripper_claw.stl"/>
</geometry>
<material name="part_3_mirror_gripper_claw_material">
<color rgba="0.231373 0.380392 0.705882 1.0"/>
</material>
</collision>
<visual>
<origin xyz="0.04015 0.0239869 -0.0345924" rpy="0.125472 -1.47775 -0.124935" />
<geometry>
<mesh filename="package://spur_gear_(16_teeth).stl"/>
</geometry>
<material name="spur_gear_(16_teeth)_material">
<color rgba="0.615686 0.811765 0.929412 1.0"/>
</material>
</visual>
<collision>
<origin xyz="0.04015 0.0239869 -0.0345924" rpy="0.125472 -1.47775 -0.124935" />
<geometry>
<mesh filename="package://spur_gear_(16_teeth).stl"/>
</geometry>
<material name="spur_gear_(16_teeth)_material">
<color rgba="0.615686 0.811765 0.929412 1.0"/>
</material>
</collision>
<visual>
<origin xyz="-0.04015 0.0239869 -0.0345924" rpy="0.0259681 -1.1065 -0.02322" />
<geometry>
<mesh filename="package://spur_gear_(16_teeth).stl"/>
</geometry>
<material name="spur_gear_(16_teeth)_material">
<color rgba="0.615686 0.811765 0.929412 1.0"/>
</material>
</visual>
<collision>
<origin xyz="-0.04015 0.0239869 -0.0345924" rpy="0.0259681 -1.1065 -0.02322" />
<geometry>
<mesh filename="package://spur_gear_(16_teeth).stl"/>
</geometry>
<material name="spur_gear_(16_teeth)_material">
<color rgba="0.615686 0.811765 0.929412 1.0"/>
</material>
</collision>
<inertial>
<origin xyz="0 0 0" rpy="0 0 0"/>
<mass value="0" />
<inertia ixx="0" ixy="0"  ixz="0" iyy="0" iyz="0" izz="0" />
</inertial>
</link>

<joint name="wrist" type="revolute">
<origin xyz="-2.498e-16 -0.155 0.08285" rpy="-1.5708 -0.0972121 -2.17303e-14" />
<parent link="forearm_link" />
<child link="gripper_assembly_link" />
<axis xyz="0 0 1"/>
<limit effort="1" velocity="20" />
<joint_properties friction="0.0"/>
</joint>

<joint name="elbow_forearm_joint" type="revolute">
<origin xyz="7.84649e-16 0.08285 -0.03115" rpy="1.5708 0.220816 1.70392e-15" />
<parent link="elbow_link" />
<child link="forearm_link" />
<axis xyz="0 0 1"/>
<limit effort="1" velocity="20" />
<joint_properties friction="0.0"/>
</joint>

<joint name="arm_elbow_joint" type="revolute">
<origin xyz="-1.32468e-15 0.18 0.0475" rpy="1.5708 9.77638e-15 -5.07927e-15" />
<parent link="arm_link" />
<child link="elbow_link" />
<axis xyz="0 0 1"/>
<limit effort="1" velocity="20" />
<joint_properties friction="0.0"/>
</joint>

<joint name="shoulder_arm" type="revolute">
<origin xyz="2.98296e-16 0.15 -8.32667e-16" rpy="2.02357e-15 -1.3664e-14 -5.20417e-16" />
<parent link="shoulder_link" />
<child link="arm_link" />
<axis xyz="0 0 1"/>
<limit effort="1" velocity="20" />
<joint_properties friction="0.0"/>
</joint>

<joint name="base_shoulder" type="revolute">
<origin xyz="8.04497e-17 0.0475 0.06" rpy="1.5708 -3.9066e-15 5.32612e-15" />
<parent link="base_link" />
<child link="shoulder_link" />
<axis xyz="0 0 1"/>
<limit effort="1" velocity="20" />
<joint_properties friction="0.0"/>
</joint>


</robot>
