<?xml version="1.0" ?>
<!-- =================================================================================== -->
<!-- |    This document was autogenerated by xacro from /home/yelwishahy/UBCOpenRobotics/ob1_arm/src/ob1_arm_description/urdf/5_dof/main_5dof.xacro | -->
<!-- |    EDITING THIS FILE BY HAND IS NOT RECOMMENDED                                 | -->
<!-- =================================================================================== -->
<robot name="robot">
    <link name="ob1_arm_base_link">
        <visual>
            <origin rpy="-1.5708 1.21431e-16 3.90606e-18" xyz="3.31402e-16 -0.0195 0.06" />
            <geometry>
                <mesh filename="package://ob1_arm_description/meshes/shoulder_y_motor.stl" />
            </geometry>
            <material name="shoulder_y_motor_material">
                <color rgba="0.615686 0.811765 0.929412 1.0" />
            </material>
        </visual>
        <collision>
            <origin rpy="-1.5708 1.21431e-16 3.90606e-18" xyz="3.31402e-16 -0.0195 0.06" />
            <geometry>
                <mesh filename="package://ob1_arm_description/meshes/shoulder_y_motor.stl" />
            </geometry>
            <material name="shoulder_y_motor_material">
                <color rgba="0.615686 0.811765 0.929412 1.0" />
            </material>
        </collision>
        <visual>
            <origin rpy="-1.5708 1.2013e-16 2.92997e-21" xyz="1.33481e-16 -0.0195 0.06" />
            <geometry>
                <mesh filename="package://ob1_arm_description/meshes/shoulder_plate.stl" />
            </geometry>
            <material name="shoulder_plate_material">
                <color rgba="0.231373 0.380392 0.705882 1.0" />
            </material>
        </visual>
        <collision>
            <origin rpy="-1.5708 1.2013e-16 2.92997e-21" xyz="1.33481e-16 -0.0195 0.06" />
            <geometry>
                <mesh filename="package://ob1_arm_description/meshes/shoulder_plate.stl" />
            </geometry>
            <material name="shoulder_plate_material">
                <color rgba="0.231373 0.380392 0.705882 1.0" />
            </material>
        </collision>
        <visual>
            <origin rpy="-1.5708 1.20997e-16 7.25353e-18" xyz="3.46418e-16 -0.0195 0.06" />
            <geometry>
                <mesh filename="package://ob1_arm_description/meshes/motor_front_support_-_shoulder.stl" />
            </geometry>
            <material name="motor_front_support_-_shoulder_material">
                <color rgba="0.498039 0.498039 0.498039 1.0" />
            </material>
        </visual>
        <collision>
            <origin rpy="-1.5708 1.20997e-16 7.25353e-18" xyz="3.46418e-16 -0.0195 0.06" />
            <geometry>
                <mesh filename="package://ob1_arm_description/meshes/motor_front_support_-_shoulder.stl" />
            </geometry>
            <material name="motor_front_support_-_shoulder_material">
                <color rgba="0.498039 0.498039 0.498039 1.0" />
            </material>
        </collision>
        <visual>
            <origin rpy="-1.5708 1.2013e-16 2.92997e-21" xyz="-6.34937e-17 -0.0195 0.06" />
            <geometry>
                <mesh filename="package://ob1_arm_description/meshes/motor_mid_support_-_shoulder.stl" />
            </geometry>
            <material name="motor_mid_support_-_shoulder_material">
                <color rgba="0.972549 0.529412 0.00392157 1.0" />
            </material>
        </visual>
        <collision>
            <origin rpy="-1.5708 1.2013e-16 2.92997e-21" xyz="-6.34937e-17 -0.0195 0.06" />
            <geometry>
                <mesh filename="package://ob1_arm_description/meshes/motor_mid_support_-_shoulder.stl" />
            </geometry>
            <material name="motor_mid_support_-_shoulder_material">
                <color rgba="0.972549 0.529412 0.00392157 1.0" />
            </material>
        </collision>
        <inertial>
            <origin rpy="0 0 0" xyz="0 0 0" />
            <mass value="0" />
            <inertia ixx="0" ixy="0" ixz="0" iyy="0" iyz="0" izz="0" />
        </inertial>
    </link>
    <link name="ob1_arm_shoulder_link">
        <visual>
            <origin rpy="3.14159 -2.02376e-31 3.10097e-18" xyz="-2.59124e-17 0.15 0.067" />
            <geometry>
                <mesh filename="package://ob1_arm_description/meshes/shoulder_linkage_-_motor.stl" />
            </geometry>
            <material name="shoulder_linkage_-_motor_material">
                <color rgba="0.921569 0.8 0.654902 1.0" />
            </material>
        </visual>
        <collision>
            <origin rpy="3.14159 -2.02376e-31 3.10097e-18" xyz="-2.59124e-17 0.15 0.067" />
            <geometry>
                <mesh filename="package://ob1_arm_description/meshes/shoulder_linkage_-_motor.stl" />
            </geometry>
            <material name="shoulder_linkage_-_motor_material">
                <color rgba="0.921569 0.8 0.654902 1.0" />
            </material>
        </collision>
        <visual>
            <origin rpy="-3.14159 6.26309e-30 3.30936e-16" xyz="8.79071e-16 6.245e-16 0.067" />
            <geometry>
                <mesh filename="package://ob1_arm_description/meshes/bicep_y_motor.stl" />
            </geometry>
            <material name="bicep_y_motor_material">
                <color rgba="0.615686 0.811765 0.929412 1.0" />
            </material>
        </visual>
        <collision>
            <origin rpy="-3.14159 6.26309e-30 3.30936e-16" xyz="8.79071e-16 6.245e-16 0.067" />
            <geometry>
                <mesh filename="package://ob1_arm_description/meshes/bicep_y_motor.stl" />
            </geometry>
            <material name="bicep_y_motor_material">
                <color rgba="0.615686 0.811765 0.929412 1.0" />
            </material>
        </collision>
        <visual>
            <origin rpy="-3.14159 1.39936e-30 -2.98503e-17" xyz="1.03715e-15 1.04083e-15 0.067" />
            <geometry>
                <mesh filename="package://ob1_arm_description/meshes/motor_front_support_-_bicep.stl" />
            </geometry>
            <material name="motor_front_support_-_bicep_material">
                <color rgba="0.498039 0.498039 0.498039 1.0" />
            </material>
        </visual>
        <collision>
            <origin rpy="-3.14159 1.39936e-30 -2.98503e-17" xyz="1.03715e-15 1.04083e-15 0.067" />
            <geometry>
                <mesh filename="package://ob1_arm_description/meshes/motor_front_support_-_bicep.stl" />
            </geometry>
            <material name="motor_front_support_-_bicep_material">
                <color rgba="0.498039 0.498039 0.498039 1.0" />
            </material>
        </collision>
        <visual>
            <origin rpy="-3.14159 1.84829e-30 -7.32146e-17" xyz="1.05677e-15 1.06859e-15 0.067" />
            <geometry>
                <mesh filename="package://ob1_arm_description/meshes/bicep_plate_-_real.stl" />
            </geometry>
            <material name="bicep_plate_-_real_material">
                <color rgba="0.980392 0.713725 0.00392157 1.0" />
            </material>
        </visual>
        <collision>
            <origin rpy="-3.14159 1.84829e-30 -7.32146e-17" xyz="1.05677e-15 1.06859e-15 0.067" />
            <geometry>
                <mesh filename="package://ob1_arm_description/meshes/bicep_plate_-_real.stl" />
            </geometry>
            <material name="bicep_plate_-_real_material">
                <color rgba="0.980392 0.713725 0.00392157 1.0" />
            </material>
        </collision>
        <visual>
            <origin rpy="-3.14159 1.97023e-30 1.36668e-16" xyz="9.52797e-16 9.57567e-16 0.067" />
            <geometry>
                <mesh filename="package://ob1_arm_description/meshes/shoulder_linkage_-_encoder.stl" />
            </geometry>
            <material name="shoulder_linkage_-_encoder_material">
                <color rgba="0.615686 0.811765 0.929412 1.0" />
            </material>
        </visual>
        <collision>
            <origin rpy="-3.14159 1.97023e-30 1.36668e-16" xyz="9.52797e-16 9.57567e-16 0.067" />
            <geometry>
                <mesh filename="package://ob1_arm_description/meshes/shoulder_linkage_-_encoder.stl" />
            </geometry>
            <material name="shoulder_linkage_-_encoder_material">
                <color rgba="0.615686 0.811765 0.929412 1.0" />
            </material>
        </collision>
        <visual>
            <origin rpy="-3.14159 2.70566e-31 -7.32146e-17" xyz="1.11651e-15 1.05471e-15 0.067" />
            <geometry>
                <mesh filename="package://ob1_arm_description/meshes/motor_mid_support_-_bicep.stl" />
            </geometry>
            <material name="motor_mid_support_-_bicep_material">
                <color rgba="0.972549 0.529412 0.00392157 1.0" />
            </material>
        </visual>
        <collision>
            <origin rpy="-3.14159 2.70566e-31 -7.32146e-17" xyz="1.11651e-15 1.05471e-15 0.067" />
            <geometry>
                <mesh filename="package://ob1_arm_description/meshes/motor_mid_support_-_bicep.stl" />
            </geometry>
            <material name="motor_mid_support_-_bicep_material">
                <color rgba="0.972549 0.529412 0.00392157 1.0" />
            </material>
        </collision>
        <inertial>
            <origin rpy="0 0 0" xyz="0 0 0" />
            <mass value="0" />
            <inertia ixx="0" ixy="0" ixz="0" iyy="0" iyz="0" izz="0" />
        </inertial>
    </link>
    <link name="ob1_arm_arm_link">
        <visual>
            <origin rpy="-3.14159 0.18918 1.80411e-15" xyz="0.00366704 -1.27676e-15 0.0666521" />
            <geometry>
                <mesh filename="package://ob1_arm_description/meshes/forearm_z_motor_shaft_collar_-_9604t12_flange-mount_shaft_collar.stl" />
            </geometry>
            <material name="forearm_z_motor_shaft_collar_-_9604t12_flange-mount_shaft_collar_material">
                <color rgba="0.498039 0.498039 0.498039 1.0" />
            </material>
        </visual>
        <collision>
            <origin rpy="-3.14159 0.18918 1.80411e-15" xyz="0.00366704 -1.27676e-15 0.0666521" />
            <geometry>
                <mesh filename="package://ob1_arm_description/meshes/forearm_z_motor_shaft_collar_-_9604t12_flange-mount_shaft_collar.stl" />
            </geometry>
            <material name="forearm_z_motor_shaft_collar_-_9604t12_flange-mount_shaft_collar_material">
                <color rgba="0.498039 0.498039 0.498039 1.0" />
            </material>
        </collision>
        <visual>
            <origin rpy="-3.14159 2.13756e-29 -1.6944e-16" xyz="-2.13371e-15 -1.38778e-16 0.067" />
            <geometry>
                <mesh filename="package://ob1_arm_description/meshes/bicep_z_motor.stl" />
            </geometry>
            <material name="bicep_z_motor_material">
                <color rgba="0.231373 0.380392 0.705882 1.0" />
            </material>
        </visual>
        <collision>
            <origin rpy="-3.14159 2.13756e-29 -1.6944e-16" xyz="-2.13371e-15 -1.38778e-16 0.067" />
            <geometry>
                <mesh filename="package://ob1_arm_description/meshes/bicep_z_motor.stl" />
            </geometry>
            <material name="bicep_z_motor_material">
                <color rgba="0.231373 0.380392 0.705882 1.0" />
            </material>
        </collision>
        <visual>
            <origin rpy="-3.14159 2.13756e-29 -1.6944e-16" xyz="-2.12851e-15 8.04912e-16 0.067" />
            <geometry>
                <mesh filename="package://ob1_arm_description/meshes/bicep_linkage_-_encoder.stl" />
            </geometry>
            <material name="bicep_linkage_-_encoder_material">
                <color rgba="0.768627 0.886275 0.952941 1.0" />
            </material>
        </visual>
        <collision>
            <origin rpy="-3.14159 2.13756e-29 -1.6944e-16" xyz="-2.12851e-15 8.04912e-16 0.067" />
            <geometry>
                <mesh filename="package://ob1_arm_description/meshes/bicep_linkage_-_encoder.stl" />
            </geometry>
            <material name="bicep_linkage_-_encoder_material">
                <color rgba="0.768627 0.886275 0.952941 1.0" />
            </material>
        </collision>
        <visual>
            <origin rpy="-3.14159 -8.22245e-32 -2.84672e-18" xyz="1.73472e-18 -2.77556e-17 0.067" />
            <geometry>
                <mesh filename="package://ob1_arm_description/meshes/bicep_linkage_-_motor.stl" />
            </geometry>
            <material name="bicep_linkage_-_motor_material">
                <color rgba="0.647059 0.647059 0.647059 1.0" />
            </material>
        </visual>
        <collision>
            <origin rpy="-3.14159 -8.22245e-32 -2.84672e-18" xyz="1.73472e-18 -2.77556e-17 0.067" />
            <geometry>
                <mesh filename="package://ob1_arm_description/meshes/bicep_linkage_-_motor.stl" />
            </geometry>
            <material name="bicep_linkage_-_motor_material">
                <color rgba="0.647059 0.647059 0.647059 1.0" />
            </material>
        </collision>
        <visual>
            <origin rpy="-3.14159 3.58504e-30 -7.91075e-17" xyz="-2.0834e-15 2.02616e-15 0.067" />
            <geometry>
                <mesh filename="package://ob1_arm_description/meshes/forearm_plate.stl" />
            </geometry>
            <material name="forearm_plate_material">
                <color rgba="0.647059 0.647059 0.647059 1.0" />
            </material>
        </visual>
        <collision>
            <origin rpy="-3.14159 3.58504e-30 -7.91075e-17" xyz="-2.0834e-15 2.02616e-15 0.067" />
            <geometry>
                <mesh filename="package://ob1_arm_description/meshes/forearm_plate.stl" />
            </geometry>
            <material name="forearm_plate_material">
                <color rgba="0.647059 0.647059 0.647059 1.0" />
            </material>
        </collision>
        <inertial>
            <origin rpy="0 0 0" xyz="0 0 0" />
            <mass value="0" />
            <inertia ixx="0" ixy="0" ixz="0" iyy="0" iyz="0" izz="0" />
        </inertial>
    </link>
    <link name="ob1_arm_elbow_link">
        <visual>
            <origin rpy="1.5708 2.04915e-16 7.13982e-16" xyz="-1.14492e-16 0.0195 0.18" />
            <geometry>
                <mesh filename="package://ob1_arm_description/meshes/forearm_motor_support.stl" />
            </geometry>
            <material name="forearm_motor_support_material">
                <color rgba="0.917647 0.917647 0.917647 1.0" />
            </material>
        </visual>
        <collision>
            <origin rpy="1.5708 2.04915e-16 7.13982e-16" xyz="-1.14492e-16 0.0195 0.18" />
            <geometry>
                <mesh filename="package://ob1_arm_description/meshes/forearm_motor_support.stl" />
            </geometry>
            <material name="forearm_motor_support_material">
                <color rgba="0.917647 0.917647 0.917647 1.0" />
            </material>
        </collision>
        <visual>
            <origin rpy="1.5708 4.02585e-18 2.26158e-19" xyz="-1.56125e-17 0.0195 0.18" />
            <geometry>
                <mesh filename="package://ob1_arm_description/meshes/forearm_intermediate_plate.stl" />
            </geometry>
            <material name="forearm_intermediate_plate_material">
                <color rgba="0.980392 0.713725 0.00392157 1.0" />
            </material>
        </visual>
        <collision>
            <origin rpy="1.5708 4.02585e-18 2.26158e-19" xyz="-1.56125e-17 0.0195 0.18" />
            <geometry>
                <mesh filename="package://ob1_arm_description/meshes/forearm_intermediate_plate.stl" />
            </geometry>
            <material name="forearm_intermediate_plate_material">
                <color rgba="0.980392 0.713725 0.00392157 1.0" />
            </material>
        </collision>
        <visual>
            <origin rpy="1.5708 1.05794e-15 1.82583e-15" xyz="7.32053e-16 0.05285 -0.03115" />
            <geometry>
                <mesh filename="package://ob1_arm_description/meshes/part_1.stl" />
            </geometry>
            <material name="part_1_material">
                <color rgba="0.615686 0.811765 0.929412 1.0" />
            </material>
        </visual>
        <collision>
            <origin rpy="1.5708 1.05794e-15 1.82583e-15" xyz="7.32053e-16 0.05285 -0.03115" />
            <geometry>
                <mesh filename="package://ob1_arm_description/meshes/part_1.stl" />
            </geometry>
            <material name="part_1_material">
                <color rgba="0.615686 0.811765 0.929412 1.0" />
            </material>
        </collision>
        <inertial>
            <origin rpy="0 0 0" xyz="0 0 0" />
            <mass value="0" />
            <inertia ixx="0" ixy="0" ixz="0" iyy="0" iyz="0" izz="0" />
        </inertial>
    </link>
    <link name="ob1_arm_forearm_link">
        <visual>
            <origin rpy="1.44226e-20 3.73615e-17 2.30593e-17" xyz="-1.43635e-15 0.21115 0.06335" />
            <geometry>
                <mesh filename="package://ob1_arm_description/meshes/end_effector_plate.stl" />
            </geometry>
            <material name="end_effector_plate_material">
                <color rgba="0.972549 0.529412 0.00392157 1.0" />
            </material>
        </visual>
        <collision>
            <origin rpy="1.44226e-20 3.73615e-17 2.30593e-17" xyz="-1.43635e-15 0.21115 0.06335" />
            <geometry>
                <mesh filename="package://ob1_arm_description/meshes/end_effector_plate.stl" />
            </geometry>
            <material name="end_effector_plate_material">
                <color rgba="0.972549 0.529412 0.00392157 1.0" />
            </material>
        </collision>
        <visual>
            <origin rpy="-1.61808e-19 9.63599e-17 2.17225e-16" xyz="1.5786e-15 0.21115 0.06335" />
            <geometry>
                <mesh filename="package://ob1_arm_description/meshes/forearm_linkage_-_encoder.stl" />
            </geometry>
            <material name="forearm_linkage_-_encoder_material">
                <color rgba="0.768627 0.886275 0.952941 1.0" />
            </material>
        </visual>
        <collision>
            <origin rpy="-1.61808e-19 9.63599e-17 2.17225e-16" xyz="1.5786e-15 0.21115 0.06335" />
            <geometry>
                <mesh filename="package://ob1_arm_description/meshes/forearm_linkage_-_encoder.stl" />
            </geometry>
            <material name="forearm_linkage_-_encoder_material">
                <color rgba="0.768627 0.886275 0.952941 1.0" />
            </material>
        </collision>
        <visual>
            <origin rpy="2.64017e-20 6.23759e-20 2.25943e-18" xyz="-1.04083e-17 0.21115 0.06335" />
            <geometry>
                <mesh filename="package://ob1_arm_description/meshes/forearm_linkage_-_motor.stl" />
            </geometry>
            <material name="forearm_linkage_-_motor_material">
                <color rgba="0.654902 0.823529 0.576471 1.0" />
            </material>
        </visual>
        <collision>
            <origin rpy="2.64017e-20 6.23759e-20 2.25943e-18" xyz="-1.04083e-17 0.21115 0.06335" />
            <geometry>
                <mesh filename="package://ob1_arm_description/meshes/forearm_linkage_-_motor.stl" />
            </geometry>
            <material name="forearm_linkage_-_motor_material">
                <color rgba="0.654902 0.823529 0.576471 1.0" />
            </material>
        </collision>
        <visual>
            <origin rpy="-2.34386e-19 3.24406e-16 6.50284e-17" xyz="4.17721e-15 0.21115 0.06335" />
            <geometry>
                <mesh filename="package://ob1_arm_description/meshes/wrist_z_motor.stl" />
            </geometry>
            <material name="wrist_z_motor_material">
                <color rgba="0.498039 0.498039 0.498039 1.0" />
            </material>
        </visual>
        <collision>
            <origin rpy="-2.34386e-19 3.24406e-16 6.50284e-17" xyz="4.17721e-15 0.21115 0.06335" />
            <geometry>
                <mesh filename="package://ob1_arm_description/meshes/wrist_z_motor.stl" />
            </geometry>
            <material name="wrist_z_motor_material">
                <color rgba="0.498039 0.498039 0.498039 1.0" />
            </material>
        </collision>
        <inertial>
            <origin rpy="0 0 0" xyz="0 0 0" />
            <mass value="0" />
            <inertia ixx="0" ixy="0" ixz="0" iyy="0" iyz="0" izz="0" />
        </inertial>
    </link>
    <joint name="ob1_arm_elbow_forearm_joint" type="revolute">
        <origin rpy="1.5708 0.0729385 1.34977e-15" xyz="7.71952e-16 0.08285 -0.03115" />
        <parent link="ob1_arm_elbow_link" />
        <child link="ob1_arm_forearm_link" />
        <axis xyz="0 0 1" />
        <limit effort="1" lower="-1.5787" upper="1.5787" velocity="20" />
        <joint_properties friction="0.0" />
        <dynamics D="1" K="7000" damping="0.003" friction="0.0" mu_coulomb="0" mu_viscous="16" />
    </joint>
    <joint name="ob1_arm_arm_elbow_joint" type="revolute">
        <origin rpy="1.5708 0.00373826 -5.38613e-15" xyz="-1.33227e-15 0.18 0.0475" />
        <parent link="ob1_arm_arm_link" />
        <child link="ob1_arm_elbow_link" />
        <axis xyz="0 0 1" />
        <limit effort="1" lower="-3.14" upper="3.14" velocity="20" />
        <joint_properties friction="0.0" />
        <dynamics D="1" K="7000" damping="0.003" friction="0.0" mu_coulomb="0" mu_viscous="16" />
    </joint>
    <joint name="ob1_arm_shoulder_arm_joint" type="revolute">
        <origin rpy="8.20328e-16 -1.37552e-14 -0.046259" xyz="2.90241e-16 0.15 -7.97973e-16" />
        <parent link="ob1_arm_shoulder_link" />
        <child link="ob1_arm_arm_link" />
        <axis xyz="0 0 1" />
        <limit effort="1" lower="-1.5787" upper="1.5787" velocity="20" />
        <joint_properties friction="0.0" />
        <dynamics D="1" K="7000" damping="0.003" friction="0.0" mu_coulomb="0" mu_viscous="16" />
    </joint>
    <joint name="ob1_arm_base_shoulder_joint" type="revolute">
        <origin rpy="1.5708 -0.0134839 4.87562e-15" xyz="8.1532e-17 0.0475 0.06" />
        <parent link="ob1_arm_base_link" />
        <child link="ob1_arm_shoulder_link" />
        <axis xyz="0 0 1" />
        <limit effort="1" lower="-1.5787" upper="1.5787" velocity="20" />
        <joint_properties friction="0.0" />
        <dynamics D="1" K="7000" damping="0.003" friction="0.0" mu_coulomb="0" mu_viscous="16" />
    </joint>
    <link name="ob1_arm_gripper_base_link">
        <visual>
            <origin rpy="-1.31921 -1.52407 -0.251324" xyz="-0.04015 0.0144875 -0.0347028" />
            <geometry>
                <mesh filename="package://ob1_arm_description/meshes/hk15328d_v5.stl" />
            </geometry>
            <material name="hk15328d_v5_material">
                <color rgba="0.952941 0.796078 0.486275 1.0" />
            </material>
        </visual>
        <collision>
            <origin rpy="-1.31921 -1.52407 -0.251324" xyz="-0.04015 0.0144875 -0.0347028" />
            <geometry>
                <mesh filename="package://ob1_arm_description/meshes/hk15328d_v5.stl" />
            </geometry>
            <material name="hk15328d_v5_material">
                <color rgba="0.952941 0.796078 0.486275 1.0" />
            </material>
        </collision>
        <visual>
            <origin rpy="0.251587 -1.52407 -0.251324" xyz="-0.04015 0.0239869 -0.0345924" />
            <geometry>
                <mesh filename="package://ob1_arm_description/meshes/spur_gear_(16_teeth).stl" />
            </geometry>
            <material name="spur_gear_(16_teeth)_material">
                <color rgba="0.615686 0.811765 0.929412 1.0" />
            </material>
        </visual>
        <collision>
            <origin rpy="0.251587 -1.52407 -0.251324" xyz="-0.04015 0.0239869 -0.0345924" />
            <geometry>
                <mesh filename="package://ob1_arm_description/meshes/spur_gear_(16_teeth).stl" />
            </geometry>
            <material name="spur_gear_(16_teeth)_material">
                <color rgba="0.615686 0.811765 0.929412 1.0" />
            </material>
        </collision>
        <visual>
            <origin rpy="-3.14159 -0.174533 4.4254e-17" xyz="-0.04 0.019 -0.0535151" />
            <geometry>
                <mesh filename="package://ob1_arm_description/meshes/spur_gear_(36_teeth).stl" />
            </geometry>
            <material name="spur_gear_(36_teeth)_material">
                <color rgba="0.647059 0.647059 0.647059 1.0" />
            </material>
        </visual>
        <collision>
            <origin rpy="-3.14159 -0.174533 4.4254e-17" xyz="-0.04 0.019 -0.0535151" />
            <geometry>
                <mesh filename="package://ob1_arm_description/meshes/spur_gear_(36_teeth).stl" />
            </geometry>
            <material name="spur_gear_(36_teeth)_material">
                <color rgba="0.647059 0.647059 0.647059 1.0" />
            </material>
        </collision>
        <visual>
            <origin rpy="-3.14159 1.01857e-14 5.54818e-17" xyz="6.93889e-18 -8.67362e-19 -1.77636e-15" />
            <geometry>
                <mesh filename="package://ob1_arm_description/meshes/part_2_gripper.stl" />
            </geometry>
            <material name="part_2_gripper_material">
                <color rgba="0.917647 0.917647 0.917647 1.0" />
            </material>
        </visual>
        <collision>
            <origin rpy="-3.14159 1.01857e-14 5.54818e-17" xyz="6.93889e-18 -8.67362e-19 -1.77636e-15" />
            <geometry>
                <mesh filename="package://ob1_arm_description/meshes/part_2_gripper.stl" />
            </geometry>
            <material name="part_2_gripper_material">
                <color rgba="0.917647 0.917647 0.917647 1.0" />
            </material>
        </collision>
        <visual>
            <origin rpy="3.10536 -1.244 -3.10728" xyz="0.04015 0.0239869 -0.0345924" />
            <geometry>
                <mesh filename="package://ob1_arm_description/meshes/spur_gear_(16_teeth).stl" />
            </geometry>
            <material name="spur_gear_(16_teeth)_material">
                <color rgba="0.615686 0.811765 0.929412 1.0" />
            </material>
        </visual>
        <collision>
            <origin rpy="3.10536 -1.244 -3.10728" xyz="0.04015 0.0239869 -0.0345924" />
            <geometry>
                <mesh filename="package://ob1_arm_description/meshes/spur_gear_(16_teeth).stl" />
            </geometry>
            <material name="spur_gear_(16_teeth)_material">
                <color rgba="0.615686 0.811765 0.929412 1.0" />
            </material>
        </collision>
        <visual>
            <origin rpy="1.10827e-14 1.0192e-14 1.02561e-16" xyz="0.04 0.024 -0.0535151" />
            <geometry>
                <mesh filename="package://ob1_arm_description/meshes/spur_gear_(36_teeth).stl" />
            </geometry>
            <material name="spur_gear_(36_teeth)_material">
                <color rgba="0.647059 0.647059 0.647059 1.0" />
            </material>
        </visual>
        <collision>
            <origin rpy="1.10827e-14 1.0192e-14 1.02561e-16" xyz="0.04 0.024 -0.0535151" />
            <geometry>
                <mesh filename="package://ob1_arm_description/meshes/spur_gear_(36_teeth).stl" />
            </geometry>
            <material name="spur_gear_(36_teeth)_material">
                <color rgba="0.647059 0.647059 0.647059 1.0" />
            </material>
        </collision>
        <visual>
            <origin rpy="1.53457 -1.244 -3.10728" xyz="0.04015 0.0144875 -0.0347028" />
            <geometry>
                <mesh filename="package://ob1_arm_description/meshes/hk15328d_v5.stl" />
            </geometry>
            <material name="hk15328d_v5_material">
                <color rgba="0.952941 0.796078 0.486275 1.0" />
            </material>
        </visual>
        <collision>
            <origin rpy="1.53457 -1.244 -3.10728" xyz="0.04015 0.0144875 -0.0347028" />
            <geometry>
                <mesh filename="package://ob1_arm_description/meshes/hk15328d_v5.stl" />
            </geometry>
            <material name="hk15328d_v5_material">
                <color rgba="0.952941 0.796078 0.486275 1.0" />
            </material>
        </collision>
        <visual>
            <origin rpy="8.11517e-13 1.55917 1.5708" xyz="0.04015 0.0144875 -0.0347028" />
            <geometry>
                <mesh filename="package://ob1_arm_description/meshes/hk15328d_v5.stl" />
            </geometry>
            <material name="hk15328d_v5_material">
                <color rgba="0.392157 0.403922 0.384314 1.0" />
            </material>
        </visual>
        <collision>
            <origin rpy="8.11517e-13 1.55917 1.5708" xyz="0.04015 0.0144875 -0.0347028" />
            <geometry>
                <mesh filename="package://ob1_arm_description/meshes/hk15328d_v5.stl" />
            </geometry>
            <material name="hk15328d_v5_material">
                <color rgba="0.392157 0.403922 0.384314 1.0" />
            </material>
        </collision>
        <visual>
            <origin rpy="-1.23792e-12 -1.55917 -1.5708" xyz="-0.04015 0.0144875 -0.0347028" />
            <geometry>
                <mesh filename="package://ob1_arm_description/meshes/hk15328d_v5.stl" />
            </geometry>
            <material name="hk15328d_v5_material">
                <color rgba="0.392157 0.403922 0.384314 1.0" />
            </material>
        </visual>
        <collision>
            <origin rpy="-1.23792e-12 -1.55917 -1.5708" xyz="-0.04015 0.0144875 -0.0347028" />
            <geometry>
                <mesh filename="package://ob1_arm_description/meshes/hk15328d_v5.stl" />
            </geometry>
            <material name="hk15328d_v5_material">
                <color rgba="0.392157 0.403922 0.384314 1.0" />
            </material>
        </collision>
        <visual>
            <origin rpy="3.14159 -6.62591e-19 -1.44439e-17" xyz="3.46945e-18 -8.67362e-19 -1.11022e-16" />
            <geometry>
                <mesh filename="package://ob1_arm_description/meshes/part_1_gripper.stl" />
            </geometry>
            <material name="part_1_gripper_material">
                <color rgba="0.615686 0.811765 0.929412 1.0" />
            </material>
        </visual>
        <collision>
            <origin rpy="3.14159 -6.62591e-19 -1.44439e-17" xyz="3.46945e-18 -8.67362e-19 -1.11022e-16" />
            <geometry>
                <mesh filename="package://ob1_arm_description/meshes/part_1_gripper.stl" />
            </geometry>
            <material name="part_1_gripper_material">
                <color rgba="0.615686 0.811765 0.929412 1.0" />
            </material>
        </collision>
        <inertial>
            <origin rpy="0 0 0" xyz="0 0 0" />
            <mass value="0" />
            <inertia ixx="0" ixy="0" ixz="0" iyy="0" iyz="0" izz="0" />
        </inertial>
    </link>
    <link name="ob1_arm_rclaw_link">
        <visual>
            <origin rpy="1.5708 -1.32447e-15 0.332485" xyz="-0.0203388 -0.0331036 0.037" />
            <geometry>
                <mesh filename="package://ob1_arm_description/meshes/part_1_mirror_gripper_claw.stl" />
            </geometry>
            <material name="part_1_mirror_gripper_claw_material">
                <color rgba="0.615686 0.811765 0.929412 1.0" />
            </material>
        </visual>
        <collision>
            <origin rpy="1.5708 -1.32447e-15 0.332485" xyz="-0.0203388 -0.0331036 0.037" />
            <geometry>
                <mesh filename="package://ob1_arm_description/meshes/part_1_mirror_gripper_claw.stl" />
            </geometry>
            <material name="part_1_mirror_gripper_claw_material">
                <color rgba="0.615686 0.811765 0.929412 1.0" />
            </material>
        </collision>
        <visual>
            <origin rpy="1.5708 2.79276e-18 -8.04372e-17" xyz="0.0106217 -0.0304372 0.012" />
            <geometry>
                <mesh filename="package://ob1_arm_description/meshes/part_3_mirror_gripper_claw.stl" />
            </geometry>
            <material name="part_3_mirror_gripper_claw_material">
                <color rgba="0.231373 0.380392 0.705882 1.0" />
            </material>
        </visual>
        <collision>
            <origin rpy="1.5708 2.79276e-18 -8.04372e-17" xyz="0.0106217 -0.0304372 0.012" />
            <geometry>
                <mesh filename="package://ob1_arm_description/meshes/part_3_mirror_gripper_claw.stl" />
            </geometry>
            <material name="part_3_mirror_gripper_claw_material">
                <color rgba="0.231373 0.380392 0.705882 1.0" />
            </material>
        </collision>
        <visual>
            <origin rpy="-1.5708 -5.46252e-16 -1.22447" xyz="0.0114671 -0.0521066 0.013" />
            <geometry>
                <mesh filename="package://ob1_arm_description/meshes/part_2_mirror_gripper_claw.stl" />
            </geometry>
            <material name="part_2_mirror_gripper_claw_material">
                <color rgba="0.647059 0.647059 0.647059 1.0" />
            </material>
        </visual>
        <collision>
            <origin rpy="-1.5708 -5.46252e-16 -1.22447" xyz="0.0114671 -0.0521066 0.013" />
            <geometry>
                <mesh filename="package://ob1_arm_description/meshes/part_2_mirror_gripper_claw.stl" />
            </geometry>
            <material name="part_2_mirror_gripper_claw_material">
                <color rgba="0.647059 0.647059 0.647059 1.0" />
            </material>
        </collision>
        <inertial>
            <origin rpy="0 0 0" xyz="0 0 0" />
            <mass value="0" />
            <inertia ixx="0" ixy="0" ixz="0" iyy="0" iyz="0" izz="0" />
        </inertial>
    </link>
    <link name="ob1_arm_lclaw_link">
        <visual>
            <origin rpy="-1.5708 -3.1668e-17 1.26775" xyz="-0.00826547 -0.051955 0.013" />
            <geometry>
                <mesh filename="package://ob1_arm_description/meshes/part_2_gripper_claw.stl" />
            </geometry>
            <material name="part_2_gripper_claw_material">
                <color rgba="0.647059 0.647059 0.647059 1.0" />
            </material>
        </visual>
        <collision>
            <origin rpy="-1.5708 -3.1668e-17 1.26775" xyz="-0.00826547 -0.051955 0.013" />
            <geometry>
                <mesh filename="package://ob1_arm_description/meshes/part_2_gripper_claw.stl" />
            </geometry>
            <material name="part_2_gripper_claw_material">
                <color rgba="0.647059 0.647059 0.647059 1.0" />
            </material>
        </collision>
        <visual>
            <origin rpy="1.5708 -6.24126e-18 1.52187e-17" xyz="-0.0106217 -0.0304372 0.012" />
            <geometry>
                <mesh filename="package://ob1_arm_description/meshes/part_3_gripper_claw.stl" />
            </geometry>
            <material name="part_3_gripper_claw_material">
                <color rgba="0.231373 0.380392 0.705882 1.0" />
            </material>
        </visual>
        <collision>
            <origin rpy="1.5708 -6.24126e-18 1.52187e-17" xyz="-0.0106217 -0.0304372 0.012" />
            <geometry>
                <mesh filename="package://ob1_arm_description/meshes/part_3_gripper_claw.stl" />
            </geometry>
            <material name="part_3_gripper_claw_material">
                <color rgba="0.231373 0.380392 0.705882 1.0" />
            </material>
        </collision>
        <visual>
            <origin rpy="1.5708 -8.52418e-17 -0.296946" xyz="0.022895 -0.0320261 0.037" />
            <geometry>
                <mesh filename="package://ob1_arm_description/meshes/part_1_gripper_claw.stl" />
            </geometry>
            <material name="part_1_gripper_claw_material">
                <color rgba="0.615686 0.811765 0.929412 1.0" />
            </material>
        </visual>
        <collision>
            <origin rpy="1.5708 -8.52418e-17 -0.296946" xyz="0.022895 -0.0320261 0.037" />
            <geometry>
                <mesh filename="package://ob1_arm_description/meshes/part_1_gripper_claw.stl" />
            </geometry>
            <material name="part_1_gripper_claw_material">
                <color rgba="0.615686 0.811765 0.929412 1.0" />
            </material>
        </collision>
        <inertial>
            <origin rpy="0 0 0" xyz="0 0 0" />
            <mass value="0" />
            <inertia ixx="0" ixy="0" ixz="0" iyy="0" iyz="0" izz="0" />
            eef
        </inertial>
    </link>
    <joint name="ob1_arm_gripper_lclaw_joint" type="revolute">
        <origin rpy="1.5708 -0.367452 -8.36952e-16" xyz="-0.04 0.008 -0.0535151" />
        <parent link="ob1_arm_gripper_base_link" />
        <child link="ob1_arm_lclaw_link" />
        <axis xyz="0 0 1" />
        <limit effort="1" lower="-3.14" upper="3.14" velocity="20" />
        <joint_properties friction="0.0" />
        <dynamics D="1" K="7000" damping="0.003" friction="0.0" mu_coulomb="0" mu_viscous="16" />
    </joint>
    <joint name="ob1_arm_gripper_rclaw_joint" type="revolute">
        <origin rpy="1.5708 0.450222 1.06462e-15" xyz="0.04 0.008 -0.0535151" />
        <parent link="ob1_arm_gripper_base_link" />
        <child link="ob1_arm_rclaw_link" />
        <axis xyz="0 0 1" />
        <limit effort="1" lower="-3.14" upper="3.14" velocity="20" />
        <joint_properties friction="0.0" />
        <dynamics D="1" K="7000" damping="0.003" friction="0.0" mu_coulomb="0" mu_viscous="16" />
    </joint>
    <link name="ob1_arm_eef_link">
        <inertial>
            <origin rpy="0 0 0" xyz="0 0 0" />
            <mass value="0" />
            <inertia ixx="0" ixy="0" ixz="0" iyy="0" iyz="0" izz="0" />
        </inertial>
    </link>
    <joint name="ob1_arm_gripper_eef_joint" type="fixed">
        <origin rpy="0 0 0" xyz="0 0 -0.11" />
        <parent link="ob1_arm_gripper_base_link" />
        <child link="ob1_arm_eef_link" />
    </joint>
    <!-- arm - gripper joint -->
    <joint name="ob1_arm_forearm_gripper_joint" type="revolute">
        <origin rpy="-1.5708 0.278795 3.7292e-15" xyz="-2.46331e-16 -0.155 0.08285" />
        <parent link="ob1_arm_forearm_link" />
        <child link="ob1_arm_gripper_base_link" />
        <axis xyz="0 0 1" />
        <limit effort="1" lower="-3.14" upper="3.14" velocity="20" />
        <joint_properties friction="0.0" />
        <dynamics D="1" K="7000" damping="0.003" friction="0.0" mu_coulomb="0" mu_viscous="16" />
    </joint>
    <!-- connect the arm to world with fixed joint -->
    <link name="world" />
    <joint name="base" type="fixed">
        <parent link="world" />
        <child link="ob1_arm_base_link" />
    </joint>
    <transmission name="trans_ob1_arm_elbow_forearm_joint">
        <type>transmission_interface/SimpleTransmission</type>
        <joint name="ob1_arm_elbow_forearm_joint">
            <hardwareInterface>hardware_interface/EffortJointInterface</hardwareInterface>
        </joint>
        <actuator name="ob1_arm_elbow_forearm_joint_motor">
            <hardwareInterface>hardware_interface/EffortJointInterface</hardwareInterface>
            <mechanicalReduction>1</mechanicalReduction>
        </actuator>
    </transmission>
    <transmission name="trans_ob1_arm_arm_elbow_joint">
        <type>transmission_interface/SimpleTransmission</type>
        <joint name="ob1_arm_arm_elbow_joint">
            <hardwareInterface>hardware_interface/EffortJointInterface</hardwareInterface>
        </joint>
        <actuator name="ob1_arm_arm_elbow_joint_motor">
            <hardwareInterface>hardware_interface/EffortJointInterface</hardwareInterface>
            <mechanicalReduction>1</mechanicalReduction>
        </actuator>
    </transmission>
    <transmission name="trans_ob1_arm_shoulder_arm_joint">
        <type>transmission_interface/SimpleTransmission</type>
        <joint name="ob1_arm_shoulder_arm_joint">
            <hardwareInterface>hardware_interface/EffortJointInterface</hardwareInterface>
        </joint>
        <actuator name="ob1_arm_shoulder_arm_joint_motor">
            <hardwareInterface>hardware_interface/EffortJointInterface</hardwareInterface>
            <mechanicalReduction>1</mechanicalReduction>
        </actuator>
    </transmission>
    <transmission name="trans_ob1_arm_base_shoulder_joint">
        <type>transmission_interface/SimpleTransmission</type>
        <joint name="ob1_arm_base_shoulder_joint">
            <hardwareInterface>hardware_interface/EffortJointInterface</hardwareInterface>
        </joint>
        <actuator name="ob1_arm_base_shoulder_joint_motor">
            <hardwareInterface>hardware_interface/EffortJointInterface</hardwareInterface>
            <mechanicalReduction>1</mechanicalReduction>
        </actuator>
    </transmission>
    <transmission name="trans_ob1_arm_gripper_lclaw_joint">
        <type>transmission_interface/SimpleTransmission</type>
        <joint name="ob1_arm_gripper_lclaw_joint">
            <hardwareInterface>hardware_interface/EffortJointInterface</hardwareInterface>
        </joint>
        <actuator name="ob1_arm_gripper_lclaw_joint_motor">
            <hardwareInterface>hardware_interface/EffortJointInterface</hardwareInterface>
            <mechanicalReduction>1</mechanicalReduction>
        </actuator>
    </transmission>
    <transmission name="trans_ob1_arm_gripper_rclaw_joint">
        <type>transmission_interface/SimpleTransmission</type>
        <joint name="ob1_arm_gripper_rclaw_joint">
            <hardwareInterface>hardware_interface/EffortJointInterface</hardwareInterface>
        </joint>
        <actuator name="ob1_arm_gripper_rclaw_joint_motor">
            <hardwareInterface>hardware_interface/EffortJointInterface</hardwareInterface>
            <mechanicalReduction>1</mechanicalReduction>
        </actuator>
    </transmission>
    <transmission name="trans_ob1_arm_forearm_gripper_joint">
        <type>transmission_interface/SimpleTransmission</type>
        <joint name="ob1_arm_forearm_gripper_joint">
            <hardwareInterface>hardware_interface/EffortJointInterface</hardwareInterface>
        </joint>
        <actuator name="ob1_arm_forearm_gripper_joint_motor">
            <hardwareInterface>hardware_interface/EffortJointInterface</hardwareInterface>
            <mechanicalReduction>1</mechanicalReduction>
        </actuator>
    </transmission>
    <gazebo>
        <plugin name="gazebo_ros_control">
            <robotNamespace>/</robotNamespace>
        </plugin>
    </gazebo>
</robot>

